Workbook
Name Spinne1: Analyse!$C$4

Sheet Guida
A1: Istruzioni per il questionario "Autovalutazione"
A2: Introduzione Avete deciso di migliorare sistematicamente la sicurezza sul lavoro e la tutela della salute nella vostra azienda facendo ricorso al progetto "sicurezza integrata". Il presente questionario costituisce un elemento centrale del progetto perché permette di verificare lo stato della sicurezza sul lavoro e tutela della salute nella vostra azienda e di raccogliere le informazioni necessarie per il progetto. Le seguenti note servono ad aiutarvi nella compilazione del questionario.
A3: 1. Struttura del questionario - Fogli di lavoro: - Dati aziendali - Figure chiave per la sicurezza sul lavoro - Autovalutazione cliente - Allegati (informazione)
A4: 2. Struttura dei singoli fogli di lavoro - È possibile compilare solo le celle previste a questo scopo; tutte le altre sono bloccate. - Le celle da compilare sono evidenziate in grigio. - Se necessario, è possibile compilare tutti gli altri campi sbloccati. - Utilizzare il tabulatore per passare da un campo all'altro.
A5: 3. Foglio di lavoro "Dati aziendali" - Inserire le informazioni richieste nella colonna "Annotazioni cliente".
A6: 4. Foglio di lavoro "Figure chiave per la sicurezza" - Indicare le funzioni presenti in azienda nella colonna "Funzione / competenza". - Compilare la colonna "Cognome / nome" per tutte le "funzioni / competenze" presenti in azienda.
A7: 5. Foglio di lavoro "Autovalutazione cliente" - Rispondere con "sì" o "no" a tutte le domande, mettendo una "x" sulla relativa casella - I commenti si possono scrivere nella colonna "Osservazione cliente". - A seconda della risposta, può risultare necessario inserire un commento alla risposta sì/no (colonna "Osservazione cliente" evidenziata in grigio). - Alcune domande si compongono di varie domande parziali. - In questi casi la domanda è evidenziata su sfondo azzurro.
A8: 6. Allegati - Per alcune domande nel foglio di lavoro "Autovalutazione cliente" si richiede obbligatoriamente di allegare la documentazione (se presente). - Il numero del rispettivo allegato va indicato nella colonna "Allegati richiesti". - Nel foglio di lavoro "Allegati" si illustrano i codici degli allegati. - Se necessario, si possono aggiungere altri allegati. - Si prega di inviare gli allegati nel formato PDF.
A9: FO.250.i.V14

Sheet Dati aziendali
A1: Dati aziendali
C2: Annotazione cliente:
A3: 1. Nome | C3: Muster AG
A4: 2. Sede principale
A5: 3. Fondazione
A6: 4. Altre sedi
A7: 5. Forma giuridica
A8: 6. Propietario
A9: 7. Organi
A10: 8. Prodotti
A11: 9. Clienti
A12: 10. Certificati tutela ambiente e qualità
A13: 11. Documenti aziendali
A14: 12. Unità organizzative dell'azienda e numero di dipendenti in ogni unità organizzative
A15: 13. Ampiezza di supervisione* nella vostra azienda *Ampiezza di supervisione: Numero dei diretti subordinati di un superiore | B15: a livello di top management
B16: a livello dirigenziale superiore
B17: a livello dirigenziale inferiore
A18: 14. Numero di dipendenti | B18: Direzione
B19: Quadri
B20: Collaboratori
B21: Apprendisti
B22: dipendenti totale
A23: 15. Tendenza di sviluppo numero di dipendenti (aumento / costante / diminuzione) | B23: Quadri
B24: Collaboratori
B25: Apprendisti
B26: Totale
A27: 16. Livello d’istruzione dei dipendenti (in %) | B27: Diploma universitario
B28: Formazione superiore (scuola politecnica / SUPSI)
B29: Formazione professionale
B30: Formazione breve
A31: 17. Nazionalità del personale
A32: 18. Lingua madre del personale
A33: 19. Pericoli principali in azienda

Sheet Persone chiavi per la sicurezza
A1: Persone chiavi per la sicurezza
A2: Funzione/competenza | B2: Cognome/nome
A3: Direzione
A14: Capo divisione (se non indicato nell'organigramma)
A26: Resp. progetto (capo progetto) / team SI
A37: Organizzazione della sicurezza
A38: Addetto/preposto alla sicurezza
A39: Ingegnere di sicurezza
A40: Esperto nell'ambito della sicurezza
A41: Assistente alla sicurezza
A42: Esperto in ergonomia
A43: Esperto di prodotti chimici
A44: Resp. radioprotezione
A45: Specialista MSSL
... A121: Altre figure chiave (se necessario compilare)

Sheet Autovalutazione
A1: Autovalutazione cliente
A2: N° | C2: Descrizione domanda | D2: Sì | E2: No | F2: Osservazione cliente | G2: Allegato richiesto
A3: 1. | B3: Principi, obiettivi e strategie
B4: Sigla collaboratore capitolo 1:
A5: 1.1. | B5: Carta dei valori, principi direttivi
A6: 1.1.1. | C6: L'azienda ha una propria carta dei valori? | G6: 1.A
A7: 1.1.2. | C7: La sicurezza e la salute dei lavoratori fanno parte dei valori dell'azienda?
A8: 1.1.3. | C8: I dipendenti sono informati sull'importanza dei valori aziendali e sulle loro conseguenze nella vita di tutti i giorni?
A9: 1.1.4. | C9: Quanto avviene in azienda è in linea con la carta dei valori?
A10: 1.1.5. | C10: Il comportamento dei superiori si ispira a determinati principi o direttive? Se sì, quali?
A11: 1.1.6. | C11: La sicurezza e la tutela della salute sono menzionati tra i principi direttivi? | G11: 1.B
A12: 1.1.7. | C12: L'azienda ha firmato la Charta della sicurezza della Suva?
A13: 1.1.8.a | C13: Nell’azienda uno dei seguenti sistemi di gestione / certificazioni è in funzione? ISO 9001, ISO 14001, ISO 45001, OHSAS18001 Se sì, quale?
A14: 1.1.8.b | C14: Vengono introdotti altri sistemi di gestione / certificazioni? Se sì, quali?
A15: 1.2. | B15: Impegno della direzione
A16: 1.2.1. | C16: La sicurezza e la tutela della salute sono principi vissuti dalla direzione e vengono promossi con decisioni, regolamenti e direttive?
A17: 1.2.2. | C17: Nella vostra azienda, la sicurezza sul lavoro ha la stessa importanza della qualità e della produttività?
A18: 1.2.3. | C18: La direzione, durante le ispezioni in azienda, affronta le situazioni e i comportamenti pericolosi?
A19: 1.2.4. | C19: Per la sicurezza sul lavoro e la tutela della salute l'azienda ha conferito un centro costi?
A20: 1.2.5.a | C20: La direzione si impegna e appoggia le seguenti attività: Valutazioni dei rischi?
A21: 1.2.5.b | C21: Audit, controlli?
A22: 1.2.5.c | C22: Indagine d'infortunio?
A23: 1.2.5.d | C23: Formazioni sul posto di lavoro?
A24: 1.2.5.e | C24: Applicazione delle misure di sicurezza?
A25: 1.2.5.f | C25: Campagne per la sicurezza sul lavoro?
A26: 1.2.5.g | C26: Campagne per la sicurezza nel tempo libero?
A27: 1.2.5.h | C27: Gestione delle assenze?
A28: 1.2.5.i | C28: Altre? Se sì, quale?
A29: 1.3. | B29: Impegno dei superiori
A30: 1.3.1.a | C30: I superiori con il loro comportamento promuovono la sicurezza e la tutela della salute: Applicano per primi le norme di sicurezza (ad esempio usare i DPI)?
A31: 1.3.1.b | C31: Impongono il rispetto delle norme di sicurezza?
A32: 1.3.1.c | C32: Altri comportamenti e incentivi? Se sì, quali?
A33: 1.3.2.a | C33: Cosa fanno i superiori per promuovere la sicurezza e la tutela della salute sul lavoro? I superiori esercitano il proprio compito mediante: Valutazioni dei rischi?
A34: 1.3.2.b | C34: Audit, controlli?
A35: 1.3.2.c | C35: Indagine d'infortunio?
A36: 1.3.2.d | C36: Formazioni sul posto di lavoro?
A37: 1.3.2.e | C37: Campagne per la sicurezza sul lavoro?
A38: 1.3.2.f | C38: Campagne per la sicurezza nel tempo libero?
A39: 1.3.2.g | C39: Gestione delle assenze?
A40: 1.3.2.h | C40: Altre? Se sì, quale?
...

Sheet Allegati
A1: Allegati richiesti (se presenti) Vi preghiamo di inviarci gli allegati, se possibile, in formato PDF.
A2: N° Allegato | B2: Descrizione
A3: 1.A | B3: Carta di valori dell'azienda
A4: 1.B | B4: Principi direttivi dell'azienda
A5: 1.C | B5: Definizione scritta degli obiettivi di sicurezza dell'azienda
A6: 2.A | B6: Organigrammi dell'azienda
A7: 2.B | B7: Descrizione del lavoro per i superiori
A8: 2.C | B8: Descrizione del lavoro per posizione senza compiti dirigenziali
A9: 2.D | B9: Descrizione del lavoro per l'addetto alla sicurezza
A10: 2.E | B10: Regolamento del collaboratore aziendale
A11: 2.F | B11: Altri documenti riguardo compiti, doveri e responsabilità in materia di sicurezza e tutela della salute
A12: 2.G | B12: esempio di una istruzione di lavoro scritta
A13: 2.H | B13: Regolamento aziendale
... A43: 11.B | B43: Obiettivi, indicatori di performance della gestione delle assenze

Sheet Analyse
A1: Firma | B1: ='Dati aziendali'!C3 -> Muster AG | C1: Datum | E1: Nr.
A2: Analyse und Bewertung für Selbstbeuteilung und Ist-Aufnahme | C2: Antwort Kunde | F2: Interviewpartner | L2: Bewertung Suva | M2: Berechnung für Diagramm
C3: ja/nein (* keine Antwort) | D3: * | E3: Bemerkungen des Kunden | F3: GL | G3: Führung | H3: HR | I3: Si Org | J3: VG | K3: MA | L3: Erfüllungsgrad in Prozent | M3: Gewicht | N3: max Punktzahl | O3: Punkte Selbst | P3: Punkte Suva | Q3: Level 1 Selbst | R3: Level 1 Suva
A4: 1 | B4: =Autovalutazione!B3 -> Principi, obiettivi e strategie | C4: =O4/N4 -> 0 | L4: =P4/N4 -> 0 | N4: =SUM(M5,M15,M29,M42,M56) -> 17 | O4: =SUM(Q5:Q63) -> 0 | P4: =SUM(R5:R63) -> 0
A5: =Autovalutazione!A5 -> 1.1. | B5: =Autovalutazione!B5 -> Carta dei valori, principi direttivi | C5: =O5/N5 -> 0 | L5: =P5/N5 -> 0 | M5: 3 | N5: =SUM(M6:M14) -> 25 | O5: =SUM(O6:O14) -> 0 | P5: =SUM(P6:P14) -> 0 | Q5: =O5/$N5*$M5 -> 0 | R5: =P5/$N5*$M5 -> 0
A6: =Autovalutazione!A6 -> 1.1.1. | B6: =Autovalutazione!C6 -> L'azienda ha una propria carta dei valori? | C6: =IF(ISBLANK(Autovalutazione!D6),0,1) -> 0 | D6: =IF(AND(Autovalutazione!D6="",Autovalutazione!E6=""),"*","") -> * | E6: =IF(ISBLANK(Autovalutazione!F6),"",Autovalutazione!F6) | M6: 3 | O6: =C6*M6 -> 0 | P6: =L6*M6 -> 0
A7: =Autovalutazione!A7 -> 1.1.2. | B7: =Autovalutazione!C7 -> La sicurezza e la salute dei lavoratori fanno parte dei valori dell'azienda? | C7: =IF(ISBLANK(Autovalutazione!D7),0,1) -> 0 | D7: =IF(AND(Autovalutazione!D7="",Autovalutazione!E7=""),"*","") -> * | E7: =IF(ISBLANK(Autovalutazione!F7),"",Autovalutazione!F7) | M7: 4 | O7: =C7*M7 -> 0 | P7: =L7*M7 -> 0
A8: =Autovalutazione!A8 -> 1.1.3. | B8: =Autovalutazione!C8 -> I dipendenti sono informati sull'importanza dei valori aziendali e sulle loro conseguenze nella vita di tutti i giorni? | C8: =IF(ISBLANK(Autovalutazione!D8),0,1) -> 0 | D8: =IF(AND(Autovalutazione!D8="",Autovalutazione!E8=""),"*","") -> * | E8: =IF(ISBLANK(Autovalutazione!F8),"",Autovalutazione!F8) | M8: 5 | O8: =C8*M8 -> 0 | P8: =L8*M8 -> 0
A9: =Autovalutazione!A9 -> 1.1.4. | B9: =Autovalutazione!C9 -> Quanto avviene in azienda è in linea con la carta dei valori? | C9: =IF(ISBLANK(Autovalutazione!D9),0,1) -> 0 | D9: =IF(AND(Autovalutazione!D9="",Autovalutazione!E9=""),"*","") -> * | E9: =IF(ISBLANK(Autovalutazione!F9),"",Autovalutazione!F9) | M9: 5 | O9: =C9*M9 -> 0 | P9: =L9*M9 -> 0
A10: =Autovalutazione!A10 -> 1.1.5. | B10: =Autovalutazione!C10 -> Il comportamento dei superiori si ispira a determinati principi o direttive? Se sì, quali? | C10: =IF(ISBLANK(Autovalutazione!D10),0,1) -> 0 | D10: =IF(AND(Autovalutazione!D10="",Autovalutazione!E10=""),"*","") -> * | E10: =IF(ISBLANK(Autovalutazione!F10),"",Autovalutazione!F10) | M10: 0 | O10: =C10*M10 -> 0 | P10: =L10*M10 -> 0
A11: =Autovalutazione!A11 -> 1.1.6. | B11: =Autovalutazione!C11 -> La sicurezza e la tutela della salute sono menzionati tra i principi direttivi? | C11: =IF(ISBLANK(Autovalutazione!D11),0,1) -> 0 | D11: =IF(AND(Autovalutazione!D11="",Autovalutazione!E11=""),"*","") -> * | E11: =IF(ISBLANK(Autovalutazione!F11),"",Autovalutazione!F11) | M11: 3 | O11: =C11*M11 -> 0 | P11: =L11*M11 -> 0
A12: =Autovalutazione!A12 -> 1.1.7. | B12: =Autovalutazione!C12 -> L'azienda ha firmato la Charta della sicurezza della Suva? | C12: =IF(ISBLANK(Autovalutazione!D12),0,1) -> 0 | D12: =IF(AND(Autovalutazione!D12="",Autovalutazione!E12=""),"*","") -> * | E12: =IF(ISBLANK(Autovalutazione!F12),"",Autovalutazione!F12) | M12: 2 | O12: =C12*M12 -> 0 | P12: =L12*M12 -> 0
A13: =Autovalutazione!A13 -> 1.1.8.a | B13: =Autovalutazione!C13 -> Nell’azienda uno dei seguenti sistemi di gestione / certificazioni è in funzione? ISO 9001, ISO 14001, ISO 45001, OHSAS18001 Se sì, quale? | C13: =IF(ISBLANK(Autovalutazione!D13),0,1) -> 0 | D13: =IF(AND(Autovalutazione!D13="",Autovalutazione!E13=""),"*","") -> * | E13: =IF(ISBLANK(Autovalutazione!F13),"",Autovalutazione!F13) | M13: 3 | O13: =C13*M13 -> 0 | P13: =L13*M13 -> 0
A14: =Autovalutazione!A14 -> 1.1.8.b | B14: =Autovalutazione!C14 -> Vengono introdotti altri sistemi di gestione / certificazioni? Se sì, quali? | C14: =IF(ISBLANK(Autovalutazione!D14),0,1) -> 0 | D14: =IF(AND(Autovalutazione!D14="",Autovalutazione!E14=""),"*","") -> * | E14: =IF(ISBLANK(Autovalutazione!F14),"",Autovalutazione!F14) | M14: 0 | O14: =C14*M14 -> 0 | P14: =L14*M14 -> 0
A15: =Autovalutazione!A15 -> 1.2. | B15: =Autovalutazione!B15 -> Impegno della direzione | C15: =O15/N15 -> 0 | L15: =P15/N15 -> 0 | M15: 5 | N15: =SUM(M16:M28) -> 14 | O15: =SUM(O16:O28) -> 0 | P15: =SUM(P16:P28) -> 0 | Q15: =O15/$N15*$M15 -> 0 | R15: =P15/$N15*$M15 -> 0
A16: =Autovalutazione!A16 -> 1.2.1. | B16: =Autovalutazione!C16 -> La sicurezza e la tutela della salute sono principi vissuti dalla direzione e vengono promossi con decisioni, regolamenti e direttive? | C16: =IF(ISBLANK(Autovalutazione!D16),0,1) -> 0 | D16: =IF(AND(Autovalutazione!D16="",Autovalutazione!E16=""),"*","") -> * | E16: =IF(ISBLANK(Autovalutazione!F16),"",Autovalutazione!F16) | M16: 5 | O16: =M16*C16 -> 0 | P16: =L16*M16 -> 0
A17: =Autovalutazione!A17 -> 1.2.2. | B17: =Autovalutazione!C17 -> Nella vostra azienda, la sicurezza sul lavoro ha la stessa importanza della qualità e della produttività? | C17: =IF(ISBLANK(Autovalutazione!D17),0,1) -> 0 | D17: =IF(AND(Autovalutazione!D17="",Autovalutazione!E17=""),"*","") -> * | E17: =IF(ISBLANK(Autovalutazione!F17),"",Autovalutazione!F17) | M17: 5 | O17: =M17*C17 -> 0 | P17: =L17*M17 -> 0
A18: =Autovalutazione!A18 -> 1.2.3. | B18: =Autovalutazione!C18 -> La direzione, durante le ispezioni in azienda, affronta le situazioni e i comportamenti pericolosi? | C18: =IF(ISBLANK(Autovalutazione!D18),0,1) -> 0 | D18: =IF(AND(Autovalutazione!D18="",Autovalutazione!E18=""),"*","") -> * | E18: =IF(ISBLANK(Autovalutazione!F18),"",Autovalutazione!F18) | M18: 3 | O18: =M18*C18 -> 0 | P18: =L18*M18 -> 0
A19: =Autovalutazione!A19 -> 1.2.4. | B19: =Autovalutazione!C19 -> Per la sicurezza sul lavoro e la tutela della salute l'azienda ha conferito un centro costi? | C19: =IF(ISBLANK(Autovalutazione!D19),0,1) -> 0 | D19: =IF(AND(Autovalutazione!D19="",Autovalutazione!E19=""),"*","") -> * | E19: =IF(ISBLANK(Autovalutazione!F19),"",Autovalutazione!F19) | M19: 1 | O19: =M19*C19 -> 0 | P19: =L19*M19 -> 0
A20: =Autovalutazione!A20 -> 1.2.5.a | B20: =Autovalutazione!C20 -> La direzione si impegna e appoggia le seguenti attività: Valutazioni dei rischi? | C20: =IF(ISBLANK(Autovalutazione!D20),0,1) -> 0 | D20: =IF(AND(Autovalutazione!D20="",Autovalutazione!E20=""),"*","") -> * | E20: =IF(ISBLANK(Autovalutazione!F20),"",Autovalutazione!F20) | M20: 0 | O20: =M20*C20 -> 0 | P20: =L20*M20 -> 0
A21: =Autovalutazione!A21 -> 1.2.5.b | B21: =Autovalutazione!C21 -> Audit, controlli? | C21: =IF(ISBLANK(Autovalutazione!D21),0,1) -> 0 | D21: =IF(AND(Autovalutazione!D21="",Autovalutazione!E21=""),"*","") -> * | E21: =IF(ISBLANK(Autovalutazione!F21),"",Autovalutazione!F21) | M21: 0 | O21: =M21*C21 -> 0 | P21: =L21*M21 -> 0
A22: =Autovalutazione!A22 -> 1.2.5.c | B22: =Autovalutazione!C22 -> Indagine d'infortunio? | C22: =IF(ISBLANK(Autovalutazione!D22),0,1) -> 0 | D22: =IF(AND(Autovalutazione!D22="",Autovalutazione!E22=""),"*","") -> * | E22: =IF(ISBLANK(Autovalutazione!F22),"",Autovalutazione!F22) | M22: 0 | O22: =M22*C22 -> 0 | P22: =L22*M22 -> 0
A23: =Autovalutazione!A23 -> 1.2.5.d | B23: =Autovalutazione!C23 -> Formazioni sul posto di lavoro? | C23: =IF(ISBLANK(Autovalutazione!D23),0,1) -> 0 | D23: =IF(AND(Autovalutazione!D23="",Autovalutazione!E23=""),"*","") -> * | E23: =IF(ISBLANK(Autovalutazione!F23),"",Autovalutazione!F23) | M23: 0 | O23: =M23*C23 -> 0 | P23: =L23*M23 -> 0
A24: =Autovalutazione!A24 -> 1.2.5.e | B24: =Autovalutazione!C24 -> Applicazione delle misure di sicurezza? | C24: =IF(ISBLANK(Autovalutazione!D24),0,1) -> 0 | D24: =IF(AND(Autovalutazione!D24="",Autovalutazione!E24=""),"*","") -> * | E24: =IF(ISBLANK(Autovalutazione!F24),"",Autovalutazione!F24) | M24: 0 | O24: =M24*C24 -> 0 | P24: =L24*M24 -> 0
A25: =Autovalutazione!A25 -> 1.2.5.f | B25: =Autovalutazione!C25 -> Campagne per la sicurezza sul lavoro? | C25: =IF(ISBLANK(Autovalutazione!D25),0,1) -> 0 | D25: =IF(AND(Autovalutazione!D25="",Autovalutazione!E25=""),"*","") -> * | E25: =IF(ISBLANK(Autovalutazione!F25),"",Autovalutazione!F25) | M25: 0 | O25: =M25*C25 -> 0 | P25: =L25*M25 -> 0
A26: =Autovalutazione!A26 -> 1.2.5.g | B26: =Autovalutazione!C26 -> Campagne per la sicurezza nel tempo libero? | C26: =IF(ISBLANK(Autovalutazione!D26),0,1) -> 0 | D26: =IF(AND(Autovalutazione!D26="",Autovalutazione!E26=""),"*","") -> * | E26: =IF(ISBLANK(Autovalutazione!F26),"",Autovalutazione!F26) | M26: 0 | O26: =M26*C26 -> 0 | P26: =L26*M26 -> 0
A27: =Autovalutazione!A27 -> 1.2.5.h | B27: =Autovalutazione!C27 -> Gestione delle assenze? | C27: =IF(ISBLANK(Autovalutazione!D27),0,1) -> 0 | D27: =IF(AND(Autovalutazione!D27="",Autovalutazione!E27=""),"*","") -> * | E27: =IF(ISBLANK(Autovalutazione!F27),"",Autovalutazione!F27) | M27: 0 | O27: =M27*C27 -> 0 | P27: =L27*M27 -> 0
A28: =Autovalutazione!A28 -> 1.2.5.i | B28: =Autovalutazione!C28 -> Altre? Se sì, quale? | C28: =IF(ISBLANK(Autovalutazione!D28),0,1) -> 0 | D28: =IF(AND(Autovalutazione!D28="",Autovalutazione!E28=""),"*","") -> * | E28: =IF(ISBLANK(Autovalutazione!F28),"",Autovalutazione!F28) | M28: 0 | O28: =M28*C28 -> 0 | P28: =L28*M28 -> 0
A29: =Autovalutazione!A29 -> 1.3. | B29: =Autovalutazione!B29 -> Impegno dei superiori | C29: =O29/N29 -> 0 | L29: =P29/N29 -> 0 | M29: 5 | N29: =SUM(M30:M41) -> 21 | O29: =SUM(O30:O41) -> 0 | P29: =SUM(P30:P41) -> 0 | Q29: =O29/$N29*$M29 -> 0 | R29: =P29/$N29*$M29 -> 0
A30: =Autovalutazione!A30 -> 1.3.1.a | B30: =Autovalutazione!C30 -> I superiori con il loro comportamento promuovono la sicurezza e la tutela della salute: Applicano per primi le norme di sicurezza (ad esempio usare i DPI)? | C30: =IF(ISBLANK(Autovalutazione!D30),0,1) -> 0 | D30: =IF(AND(Autovalutazione!D30="",Autovalutazione!E30=""),"*","") -> * | E30: =IF(ISBLANK(Autovalutazione!F30),"",Autovalutazione!F30) | M30: 5 | O30: =M30*C30 -> 0 | P30: =L30*M30 -> 0
A31: =Autovalutazione!A31 -> 1.3.1.b | B31: =Autovalutazione!C31 -> Impongono il rispetto delle norme di sicurezza? | C31: =IF(ISBLANK(Autovalutazione!D31),0,1) -> 0 | D31: =IF(AND(Autovalutazione!D31="",Autovalutazione!E31=""),"*","") -> * | E31: =IF(ISBLANK(Autovalutazione!F31),"",Autovalutazione!F31) | M31: 5 | O31: =M31*C31 -> 0 | P31: =L31*M31 -> 0
A32: =Autovalutazione!A32 -> 1.3.1.c | B32: =Autovalutazione!C32 -> Altri comportamenti e incentivi? Se sì, quali? | C32: =IF(ISBLANK(Autovalutazione!D32),0,1) -> 0 | D32: =IF(AND(Autovalutazione!D32="",Autovalutazione!E32=""),"*","") -> * | E32: =IF(ISBLANK(Autovalutazione!F32),"",Autovalutazione!F32) | M32: 0 | O32: =M32*C32 -> 0 | P32: =L32*M32 -> 0
A33: =Autovalutazione!A33 -> 1.3.2.a | B33: =Autovalutazione!C33 -> Cosa fanno i superiori per promuovere la sicurezza e la tutela della salute sul lavoro? I superiori esercitano il proprio compito mediante: Valutazioni dei rischi? | C33: =IF(ISBLANK(Autovalutazione!D33),0,1) -> 0 | D33: =IF(AND(Autovalutazione!D33="",Autovalutazione!E33=""),"*","") -> * | E33: =IF(ISBLANK(Autovalutazione!F33),"",Autovalutazione!F33) | M33: 0 | O33: =M33*C33 -> 0 | P33: =L33*M33 -> 0
A34: =Autovalutazione!A34 -> 1.3.2.b | B34: =Autovalutazione!C34 -> Audit, controlli? | C34: =IF(ISBLANK(Autovalutazione!D34),0,1) -> 0 | D34: =IF(AND(Autovalutazione!D34="",Autovalutazione!E34=""),"*","") -> * | E34: =IF(ISBLANK(Autovalutazione!F34),"",Autovalutazione!F34) | M34: 2 | O34: =M34*C34 -> 0 | P34: =L34*M34 -> 0
A35: =Autovalutazione!A35 -> 1.3.2.c | B35: =Autovalutazione!C35 -> Indagine d'infortunio? | C35: =IF(ISBLANK(Autovalutazione!D35),0,1) -> 0 | D35: =IF(AND(Autovalutazione!D35="",Autovalutazione!E35=""),"*","") -> * | E35: =IF(ISBLANK(Autovalutazione!F35),"",Autovalutazione!F35) | M35: 2 | O35: =M35*C35 -> 0 | P35: =L35*M35 -> 0
A36: =Autovalutazione!A36 -> 1.3.2.d | B36: =Autovalutazione!C36 -> Formazioni sul posto di lavoro? | C36: =IF(ISBLANK(Autovalutazione!D36),0,1) -> 0 | D36: =IF(AND(Autovalutazione!D36="",Autovalutazione!E36=""),"*","") -> * | E36: =IF(ISBLANK(Autovalutazione!F36),"",Autovalutazione!F36) | M36: 2 | O36: =M36*C36 -> 0 | P36: =L36*M36 -> 0
A37: =Autovalutazione!A37 -> 1.3.2.e | B37: =Autovalutazione!C37 -> Campagne per la sicurezza sul lavoro? | C37: =IF(ISBLANK(Autovalutazione!D37),0,1) -> 0 | D37: =IF(AND(Autovalutazione!D37="",Autovalutazione!E37=""),"*","") -> * | E37: =IF(ISBLANK(Autovalutazione!F37),"",Autovalutazione!F37) | M37: 0 | O37: =M37*C37 -> 0 | P37: =L37*M37 -> 0
A38: =Autovalutazione!A38 -> 1.3.2.f | B38: =Autovalutazione!C38 -> Campagne per la sicurezza nel tempo libero? | C38: =IF(ISBLANK(Autovalutazione!D38),0,1) -> 0 | D38: =IF(AND(Autovalutazione!D38="",Autovalutazione!E38=""),"*","") -> * | E38: =IF(ISBLANK(Autovalutazione!F38),"",Autovalutazione!F38) | M38: 0 | O38: =M38*C38 -> 0 | P38: =L38*M38 -> 0
A39: =Autovalutazione!A39 -> 1.3.2.g | B39: =Autovalutazione!C39 -> Gestione delle assenze? | C39: =IF(ISBLANK(Autovalutazione!D39),0,1) -> 0 | D39: =IF(AND(Autovalutazione!D39="",Autovalutazione!E39=""),"*","") -> * | E39: =IF(ISBLANK(Autovalutazione!F39),"",Autovalutazione!F39) | M39: 2 | O39: =M39*C39 -> 0 | P39: =L39*M39 -> 0
A40: =Autovalutazione!A40 -> 1.3.2.h | B40: =Autovalutazione!C40 -> Altre? Se sì, quale? | C40: =IF(ISBLANK(Autovalutazione!D40),0,1) -> 0 | D40: =IF(AND(Autovalutazione!D40="",Autovalutazione!E40=""),"*","") -> * | E40: =IF(ISBLANK(Autovalutazione!F40),"",Autovalutazione!F40) | M40: 0 | O40: =M40*C40 -> 0 | P40: =L40*M40 -> 0
...

Sheet Auswertungen
B2: Legende im Spinnendiagramm:
A3: Erfüllungsgrad | B3: ="Autovalutazione "&Analyse!B1 -> Autovalutazione Muster AG | D3: Valutazione Suva | G3: Delta Suva - Kunde
B4: Berechnung automatisch | C4: Spinnendiagramm überschreibbar | D4: Berechnung automatisch | E4: Spinnendiagramm überschreibbar | G4: Zur Information
A5: =CONCATENATE(Analyse!A4," ",Analyse!B4) -> 1 Principi, obiettivi e strategie | B5: =Analyse!C4 -> 0 | C5: =B5 -> 0 | D5: =Analyse!L4 -> 0 | E5: =D5 -> 0 | G5: =E5-C5 -> 0
A6: =CONCATENATE(Analyse!A64," ",Analyse!B64) -> 2. Organizzazione | B6: =Analyse!C64 -> 0 | C6: =B6 -> 0 | D6: =Analyse!L64 -> 0 | E6: =D6 -> 0 | G6: =E6-C6 -> 0
A7: =CONCATENATE(Analyse!A144," ",Analyse!B144) -> 3. Qualificazione, formazione, comunicazione | B7: =Analyse!C144 -> 0 | C7: =B7 -> 0 | D7: =Analyse!L144 -> 0 | E7: =D7 -> 0 | G7: =E7-C7 -> 0
A8: =CONCATENATE(Analyse!A240," ",Analyse!B240) -> 4. Norme di sicurezza | B8: =Analyse!C240 -> 0.5 | C8: =B8 -> 0.5 | D8: =Analyse!L240 -> 0 | E8: =D8 -> 0 | G8: =E8-C8 -> -0.5
A9: =CONCATENATE(Analyse!A319," ",Analyse!B319) -> 5. Individuazione dei pericoli, valutazione dei rischi | B9: =Analyse!C319 -> 0.034090909 | C9: =B9 -> 0.034090909 | D9: =Analyse!L319 -> 0.034090909 | E9: =D9 -> 0.034090909 | G9: =E9-C9 -> 0
A10: =CONCATENATE(Analyse!A368," ",Analyse!B368) -> 6. Misure | B10: =Analyse!C368 -> 0 | C10: =B10 -> 0 | D10: =Analyse!L368 -> 0 | E10: =D10 -> 0 | G10: =E10-C10 -> 0
A11: =CONCATENATE(Analyse!A392," ",Analyse!B392) -> 7. Organizzazione per i casi di emergenza | B11: =Analyse!C392 -> 0 | C11: =B11 -> 0 | D11: =Analyse!L392 -> 0 | E11: =D11 -> 0 | G11: =E11-C11 -> 0
A12: =CONCATENATE(Analyse!A429," ",Analyse!B429) -> 8. Partecipazione | B12: =Analyse!C429 -> 0 | C12: =B12 -> 0 | D12: =Analyse!L429 -> 0 | E12: =D12 -> 0 | G12: =E12-C12 -> 0
A13: =CONCATENATE(Analyse!A445," ",Analyse!B445) -> 9. Tutela della salute | B13: =Analyse!C445 -> 0.15833333 | C13: =B13 -> 0.15833333 | D13: =Analyse!L445 -> 0.15833333 | E13: =D13 -> 0.15833333 | G13: =E13-C13 -> 0
A14: =CONCATENATE(Analyse!A556," ",Analyse!B556) -> 10. Controllo | B14: =Analyse!C556 -> 0 | C14: =B14 -> 0 | D14: =Analyse!L556 -> 0 | E14: =D14 -> 0 | G14: =E14-C14 -> 0
A15: =CONCATENATE(Analyse!A587," ",Analyse!B587) -> 11. Assenze | B15: =Analyse!C587 -> 0 | C15: =B15 -> 0 | D15: =Analyse!L587 -> 0 | E15: =D15 -> 0 | G15: =E15-C15 -> 0
A16: =CONCATENATE(Analyse!A607," ",Analyse!B607) -> 12 Sicurezza nel tempo libero (parte facoltativa) | B16: =Analyse!C607 -> 0 | C16: =B16 -> 0 | D16: =Analyse!L607 -> 0 | E16: =D16 -> 0 | G16: =E16-C16 -> 0
A17: =CONCATENATE(Analyse!A629," ",Analyse!B629) -> 13 GSA: gestione della salute in azienda (parte facoltativa) | B17: =Analyse!C629 -> 0 | C17: =B17 -> 0 | D17: =Analyse!L629 -> 0 | E17: =D17 -> 0 | G17: =E17-C17 -> 0
A18: =CONCATENATE(Analyse!A657," ",Analyse!B657) -> 14 Ampliamento per l'ISO 45001 (parte facoltativa) | B18: =Analyse!C657 -> 0 | C18: =B18 -> 0 | D18: =Analyse!L657 -> 0 | E18: =D18 -> 0 | G18: =E18-C18 -> 0

Sheet Versionenprotokoll
A1: Versionenprotokoll
A3: Version | B3: Sheet | C3: Änderungen
A4: Version 14 | B4: Selbstbeurteilung Kunde | C4: Französische Übersetzung der Frage 2.3.2.3. korrigiert
A5: Freigabe
A6: 45061
B7: Anleitung | C7: Versionnummer aktualisiert
B8: Selbstbeurteilung Kunde | C8: Versionnummer aktualisiert
A9: Version 13 | B9: verschiedene | C9: Formulierungen in der französischen Version kontrolliert und korrigiert durch Sandrine Casanova.
A10: Freigabe
A11: 45028
B12: Anleitung | C12: Versionnummer aktualisiert
B13: Selbstbeurteilung Kunde | C13: Versionnummer aktualisiert
A14: Version 12 | B14: Selbstbeurteilung Kunde | C14: In Fusszeile des Ausdrucks Versionnummer aktualisiert
A15: Freigabe | B15: Anleitung | C15: Versionnummer aktualisiert
A16: 44841 | B16: Analyse | C16: Spalte D "*" eingefügt zur Visualisierung nicht beantwortet.
B17: Analyse | C17: Spalte C formatiert für Visualisierung Ja / Nein
B18: Selbstbeurteilung Kunde | C18: In 9.9.8 und 9.9.9 Fragen 9.9 und 9.3 aus dem ASA-Systemkontrolle Kategorie 3.1 (EKAS 6074/3.1.d 02.2021) eingefügt.
A20: Version 11 | B20: Selbstbeurteilung Kunde | C20: In Fusszeile des Ausdrucks Versionnummer aktualisiert
A21: Freigabe | B21: Anleitung | C21: Versionnummer aktualisiert
A22: 43712 | B22: Selbstbeurteilung Kunde | C22: Anpassung von OHSAS 18001 auf ISO 45001
B23: Generell | C23: Suva Logo aktualisiert
B24: Analyse | C24: Anpassungen von OHSAS 18001 auf ISO 45001
A25: Version 10 | B25: Selbstbeurteilung Kunde | C25: In Fusszeile des Ausdrucks Versionnummer aktualisiert
A26: Freigabe | B26: Anleitung | C26: Versionnummer aktualisiert
A27: 42913 | B27: Analyse | C27: 2.1.3. Gewicht von 1 auf 2 erhöht
B28: Analyse | C28: 1.1.7. Gewicht von 5 auf 2 reduziert
B29: Analyse | C29: 4.1.3. Gewicht von 3 auf 1 reduziert
B30: Analyse | C30: 3.1. falscher Titel korrigiert (Zellenbezug 149 anstatt 148)
B31: Analyse | C31: 4.2. Gewicht von 1 auf 0 reduziert
B32: Analyse | C32: 4.3. Gewicht von 1 auf 2 erhöht
B33: Spinnendiagramme | C33: Legende "Beurteilung Suva" von D3 in Sheet Auswertungen
A35: Version 09 | B35: Selbstbeurteilung Kunde | C35: In Fusszeile des Ausdrucks Versionnummer aktualisiert
A36: Freigabe | B36: Anleitung | C36: Versionnummer aktualisiert
A37: 42555 | B37: Analyse | C37: Gewicht von Kapitel 9.3. physische Belastungen von 3 auf 0 geändert
B38: Analyse | C38: 9.10. Summierung der eigenen Punkte: Formel auf richtige Spalte korrigiert
B39: Analyse | C39: 4.8. Bewertung für Stichproben eingeführt
B40: Analyse | C40: 4.1.3 Gewicht für Booklet von 5 auf 3 reduziert
B41: Diagramme | C41: Rahmenlinie entfernt
A42: Version 08 | B42: Selbstbeurteilung Kunde | C42: In Fusszeile des Ausdrucks Versionnummer aktualisiert
A43: Freigabe | B43: Anleitung | C43: Versionnummer aktualisiert
...
