Workbook
Name Spinne1: Analyse!$C$4

Sheet Instructions
A1: Instructions relatives au questionnaire «Autoévaluation»
A2: Introduction Vous avez décidé de renforcer de manière systématique la sécurité au travail et la protection de la santé au sein de votre entreprise par le biais du projet «Sécurité intégrée». Dans cette optique, ce questionnaire constitue un outil essentiel. Il vous permet de contrôler l’état actuel de la sécurité au travail et de la protection de la santé au niveau interne et de collecter les informations nécessaires à la réalisation du projet. Les remarques ci-après doivent vous aider à remplir le questionnaire.
A3: 1. Structure du questionnaire - Tableaux - Informations concernant l’entreprise - Personnes clés pour la sécurité au travail - Autoévaluation client - Aperçu des annexes (à titre informatif)
A4: 2. Structure des différents tableaux - Seules les cellules à compléter sont déverrouillées. - Les plages des cellules à remplir sont grisées. - Les autres plages déverrouillées peuvent être remplies au cas par cas. - La touche de tabulation permet de passer rapidement d’un champ déverrouillé au suivant.
A5: 3. Tableau «Informations concernant l’entreprise» - Complétez la colonne «Saisie client» avec les informations demandées.
A6: 4. Tableur «Personnes clés pour la sécurité au travail» - Complétez la colonne «Fonction/Compétence» avec les fonctions existantes au sein de l’entreprise. - Remplissez la colonne «Nom/Prénom» pour toutes les «Fonctions/Compétences» mentionnées qui existent au sein de l’entreprise.
A7: 5. Tableau «Autoévaluation client» - Répondez à toutes les questions par «Oui» ou par «Non» en insérant le symbole «x» dans le champ correspondant. - Vous pouvez ajouter un commentaire dans la colonne «Remarque client» prévue à cet effet. - En fonction de votre réponse à certaines questions, un commentaire peut être obligatoire (dans ce cas, la colonne «Remarque client» est grisée). - Certaines questions sont en plusieurs parties. - Dans ce cas, la question principale est affichée sur fond bleu.
A8: 6. Annexes - Certaines questions du tableau «Autoévaluation client» nécessitent impérativement une annexe à des fins de documentation (si disponible). - Le numéro de l’annexe en question est indiqué dans la colonne «Annexe nécessaire». - Tous les numéros des annexes sont indiqués dans le tableau «Aperçu des annexes». - Des annexes supplémentaires peuvent être jointes en cas de besoin. - Merci de bien vouloir nous transmettre les annexes si possible au format pdf.
A9: FO.250.f.V14

Sheet Fiche signalétique
A1: Fiche signalétique de l'entreprise
C2: Saisie client :
A3: 1. Nom de l'entreprise | C3: Exemple SA
A4: 2. Siège social
A5: 3. Date de création
A6: 4. Sites
A7: 5. Forme juridique
A8: 6. Propriétaires
A9: 7. Organes
A10: 8. Produits
A11: 9. Clientèle
A12: 10. Certificats environnementaux et de qualité
A13: 11. Documents de l'entreprise
A14: 12. Unités organisationnelles de l'entreprise et nombre d'employés dans chaque Unité organisationnelle
A15: 13. Etendue des responsabilités* dans votre entreprise *Etendue des responsabilités = nombre de collaborateurs directement subordonnés à un supérieur hiérarchique | B15: au niveau des cadres supérieurs
B16: au niveau des cadres moyens
B17: au niveau des cadres inférieurs
A18: 14. Nombre d'employés | B18: Direction
B19: Cadres
B20: Collaborateurs
B21: Apprentis
B22: Total collaborateurs
A23: 15. Evolution tendancielle Nombre d'employés (en hausse / constant / en diminution) | B23: Membres des cadres
B24: Collaborateurs
B25: Apprentis
B26: Total
A27: 16. Statut de formation des employés (en %) | B27: Diplôme universitaire
B28: Formation profes-sionnelle supérieure (HES/ETS/ET)
B29: Formation professionnelle
B30: Formation élémentaire
A31: 17. Nationalités des employés
A32: 18. Langues maternelles des employés
A33: 19. Dangers spécifiques à l'exploitation

Sheet Interlocuteurs sécurité
A1: Interlocuteurs de la sécurité au travail
A2: Fonction / compétences | B2: Nom / prénom
A3: Direction
A14: Chef de division (pour autant que la réponse ne figure pas dans l'organigramme annexé)
A26: Direction et team de projet IS
A37: Organisation de la sécurité
A38: Coordinateur de la sécurité
A39: Ingénieur de sécurité
A40: Chargé de sécurité
A41: Assistant de sécurité
A42: Coordinateur de l'ergonomie
A43: Personne de contact pour les produits chimiques
A44: Responsable de la radioprotection
A45: Spécialistes MSST
... A121: Autres employés clés (à remplir si nécessaire)

Sheet Autoévaluation client
A1: Autoévaluation par le client
A2: N° | C2: Description question | D2: Oui | E2: Non | F2: Remarque du client | G2: Annexe requise
A3: 1. | B3: Ligne de conduite, objectifs et stratégie
B4: Visa gestionnaire du dossier Chapitre 1:
A5: 1.1. | B5: Ligne de conduite de l'entreprise, principes directeurs
A6: 1.1.1. | C6: L'entreprise dispose-t-elle d'une charte d'entreprise? | G6: 1.A
A7: 1.1.2. | C7: La sécurité et la santé du personnel font-elles partie de la charte d'entreprise?
A8: 1.1.3. | C8: Les collobrateurs sont-ils informés de la philosophie et des conséquences pratiques de la charte d'entreprise?
A9: 1.1.4. | C9: Le reflet de la situation dans l'entreprise correspond-il à la charte d'entreprise?
A10: 1.1.5. | C10: Le comportement des supérieurs dans votre entreprise est-il déterminé par des principes ou des directives de conduite spécifiques? Si oui, lesquels?
A11: 1.1.6. | C11: La sécurité et la protection de la santé sont-elle expressément intégrées dans les principes ou les directives de conduite? | G11: 1.B
A12: 1.1.7. | C12: Est-ce que la société a signé la Charte de sécurité de la Suva?
A13: 1.1.8.a | C13: L'un des systèmes de management / certifications suivants est-il en vigueur: ISO 9001, ISO 14001, ISO 45001, OHSAS18001 ? Si oui, lequel?
A14: 1.1.8.b | C14: Un autre système de management / certifications est-il en vigueur? Si oui, lequel?
A15: 1.2. | B15: Engagement de la direction
A16: 1.2.1. | C16: La direction de l'entreprise montre-t-elle l'exemple à suivre en matière de sécurité et de santé à l'aide d'exigences, de décisions, de règles et d'instructions concrètes?
A17: 1.2.2. | C17: Votre entreprise accorde-t-elle à la sécurité au travail la même valeur qu'à la qualité et à la productivité?
A18: 1.2.3. | C18: La direction aborde-t-elle les situations et les comportements à risque lors de ses inspections dans les entreprises?
A19: 1.2.4. | C19: Le budget prévoit-il des ressources pour la sécurité au travail et la protection de la santé?
A20: 1.2.5.a | C20: La direction soutient-elle dans l'entreprise... les évaluations du risque?
A21: 1.2.5.b | C21: les audits, les contrôles?
A22: 1.2.5.c | C22: les analyses d'accidents?
A23: 1.2.5.d | C23: la formation des collaborateurs sur le lieu de travail?
A24: 1.2.5.e | C24: la mise en œuvre de mesures adéquates?
A25: 1.2.5.f | C25: les campagnes en faveur de la sécurité au travail?
A26: 1.2.5.g | C26: les campagnes en faveur de la sécurité durant les loisirs?
A27: 1.2.5.h | C27: la gestion des absences?
A28: 1.2.5.i | C28: autres? Si oui, lesquels?
A29: 1.3. | B29: Engagement des supérieurs hiérarchiques
A30: 1.3.1.a | C30: Les supérieurs hiérarchiques promeuvent-ils la sécurité et la santé : en se conformant aux prescriptions de sécurité (par ex. le port de l'équipement de protection individuelle (EPI))?
A31: 1.3.1.b | C31: en faisant respecter l'observation des prescriptions de sécurité?
A32: 1.3.1.c | C32: par d'autres formes d'incitations? Si oui, lesquelles?
A33: 1.3.2.a | C33: Les supérieurs hiérarchiques de l'entreprise s'engagent-ils pour la sécurité et la santé des employés, en réalisant... des évaluations de risque?
A34: 1.3.2.b | C34: des audits, des contrôles?
A35: 1.3.2.c | C35: des analyses d'accidents?
A36: 1.3.2.d | C36: de la formation des collaborateurs à la place de travail?
A37: 1.3.2.e | C37: des campagnes en faveur de la sécurité au travail?
A38: 1.3.2.f | C38: des campagnes en faveur de la sécurité durant les loisirs?
A39: 1.3.2.g | C39: la gestion des absences?
A40: 1.3.2.h | C40: d'autres actions? Si oui, lesquelles?
...

Sheet Annexes
A1: Annexes nécessaires (si disponibles) Veuillez nous envoyer les documents suivants, si possible au format PDF.
A2: Annexes N° | B2: Description
A3: 1.A | B3: La charte des valeurs de l'entreprise
A4: 1.B | B4: Principes / directives de conduite de l'entreprise
A5: 1.C | B5: Définition écrite des objectifs de sécurité de l'entreprise
A6: 2.A | B6: Organigramme de l'entreprise
A7: 2.B | B7: Cahier des charges pour les supérieur
A8: 2.C | B8: Cahier des charges pour tout poste sans responsabilité de gestion
A9: 2.D | B9: Cahier des charges pour le coordinateur de la sécurité
A10: 2.E | B10: Règlement du personnel de l'entreprise
A11: 2.F | B11: Autres documents qui réglementent les tâches, les compétences et les responsabilités concernant la sécurité et la santé
A12: 2.G | B12: Exemple d'une instruction de travail écrite
A13: 2.H | B13: Règlement d'entreprise
... A43: 11.B | B43: Objectifs et chiffres indicateurs sociaux de la gestion des absences

Sheet Analyse
A1: Firma | B1: ='Fiche signalétique'!C3 -> Exemple SA | C1: Datum | E1: Nr.
A2: Analyse und Bewertung für Selbstbeuteilung und Ist-Aufnahme | C2: Antwort Kunde | F2: Interviewpartner | L2: Bewertung Suva | M2: Berechnung für Diagramm
C3: ja/nein (* keine Antwort) | E3: Bemerkungen des Kunden | F3: GL | G3: Führung | H3: HR | I3: Si Org | J3: VG | K3: MA | L3: Erfüllungsgrad in Prozent | M3: Gewicht | N3: max Punktzahl | O3: Punkte Selbst | P3: Punkte Suva | Q3: Level 1 Selbst | R3: Level 1 Suva
A4: 1 | B4: ='Autoévaluation client'!B3 -> Ligne de conduite, objectifs et stratégie | C4: =O4/N4 -> 0 | L4: =P4/N4 -> 0 | N4: =SUM(M5,M15,M29,M42,M56) -> 17 | O4: =SUM(Q5:Q63) -> 0 | P4: =SUM(R5:R63) -> 0
A5: ='Autoévaluation client'!A5 -> 1.1. | B5: ='Autoévaluation client'!B5 -> Ligne de conduite de l'entreprise, principes directeurs | C5: =O5/N5 -> 0 | L5: =P5/N5 -> 0 | M5: 3 | N5: =SUM(M6:M14) -> 25 | O5: =SUM(O6:O14) -> 0 | P5: =SUM(P6:P14) -> 0 | Q5: =O5/$N5*$M5 -> 0 | R5: =P5/$N5*$M5 -> 0
A6: ='Autoévaluation client'!A6 -> 1.1.1. | B6: ='Autoévaluation client'!C6 -> L'entreprise dispose-t-elle d'une charte d'entreprise? | C6: =IF(ISBLANK('Autoévaluation client'!D6),0,1) -> 0 | D6: =IF(AND('Autoévaluation client'!D6="",'Autoévaluation client'!E6=""),"*","") -> * | M6: 3 | O6: =C6*M6 -> 0 | P6: =L6*M6 -> 0
A7: ='Autoévaluation client'!A7 -> 1.1.2. | B7: ='Autoévaluation client'!C7 -> La sécurité et la santé du personnel font-elles partie de la charte d'entreprise? | C7: =IF(ISBLANK('Autoévaluation client'!D7),0,1) -> 0 | D7: =IF(AND('Autoévaluation client'!D7="",'Autoévaluation client'!E7=""),"*","") -> * | E7: =IF(ISBLANK('Autoévaluation client'!F7),"",'Autoévaluation client'!F7) | M7: 4 | O7: =C7*M7 -> 0 | P7: =L7*M7 -> 0
A8: ='Autoévaluation client'!A8 -> 1.1.3. | B8: ='Autoévaluation client'!C8 -> Les collobrateurs sont-ils informés de la philosophie et des conséquences pratiques de la charte d'entreprise? | C8: =IF(ISBLANK('Autoévaluation client'!D8),0,1) -> 0 | D8: =IF(AND('Autoévaluation client'!D8="",'Autoévaluation client'!E8=""),"*","") -> * | E8: =IF(ISBLANK('Autoévaluation client'!F8),"",'Autoévaluation client'!F8) | M8: 5 | O8: =C8*M8 -> 0 | P8: =L8*M8 -> 0
A9: ='Autoévaluation client'!A9 -> 1.1.4. | B9: ='Autoévaluation client'!C9 -> Le reflet de la situation dans l'entreprise correspond-il à la charte d'entreprise? | C9: =IF(ISBLANK('Autoévaluation client'!D9),0,1) -> 0 | D9: =IF(AND('Autoévaluation client'!D9="",'Autoévaluation client'!E9=""),"*","") -> * | E9: =IF(ISBLANK('Autoévaluation client'!F9),"",'Autoévaluation client'!F9) | M9: 5 | O9: =C9*M9 -> 0 | P9: =L9*M9 -> 0
A10: ='Autoévaluation client'!A10 -> 1.1.5. | B10: ='Autoévaluation client'!C10 -> Le comportement des supérieurs dans votre entreprise est-il déterminé par des principes ou des directives de conduite spécifiques? Si oui, lesquels? | C10: =IF(ISBLANK('Autoévaluation client'!D10),0,1) -> 0 | D10: =IF(AND('Autoévaluation client'!D10="",'Autoévaluation client'!E10=""),"*","") -> * | E10: =IF(ISBLANK('Autoévaluation client'!F10),"",'Autoévaluation client'!F10) | M10: 0 | O10: =C10*M10 -> 0 | P10: =L10*M10 -> 0
A11: ='Autoévaluation client'!A11 -> 1.1.6. | B11: ='Autoévaluation client'!C11 -> La sécurité et la protection de la santé sont-elle expressément intégrées dans les principes ou les directives de conduite? | C11: =IF(ISBLANK('Autoévaluation client'!D11),0,1) -> 0 | D11: =IF(AND('Autoévaluation client'!D11="",'Autoévaluation client'!E11=""),"*","") -> * | E11: =IF(ISBLANK('Autoévaluation client'!F11),"",'Autoévaluation client'!F11) | M11: 3 | O11: =C11*M11 -> 0 | P11: =L11*M11 -> 0
A12: ='Autoévaluation client'!A12 -> 1.1.7. | B12: ='Autoévaluation client'!C12 -> Est-ce que la société a signé la Charte de sécurité de la Suva? | C12: =IF(ISBLANK('Autoévaluation client'!D12),0,1) -> 0 | D12: =IF(AND('Autoévaluation client'!D12="",'Autoévaluation client'!E12=""),"*","") -> * | E12: =IF(ISBLANK('Autoévaluation client'!F12),"",'Autoévaluation client'!F12) | M12: 2 | O12: =C12*M12 -> 0 | P12: =L12*M12 -> 0
A13: ='Autoévaluation client'!A13 -> 1.1.8.a | B13: ='Autoévaluation client'!C13 -> L'un des systèmes de management / certifications suivants est-il en vigueur: ISO 9001, ISO 14001, ISO 45001, OHSAS18001 ? Si oui, lequel? | C13: =IF(ISBLANK('Autoévaluation client'!D13),0,1) -> 0 | D13: =IF(AND('Autoévaluation client'!D13="",'Autoévaluation client'!E13=""),"*","") -> * | E13: =IF(ISBLANK('Autoévaluation client'!F13),"",'Autoévaluation client'!F13) | M13: 3 | O13: =C13*M13 -> 0 | P13: =L13*M13 -> 0
A14: ='Autoévaluation client'!A14 -> 1.1.8.b | B14: ='Autoévaluation client'!C14 -> Un autre système de management / certifications est-il en vigueur? Si oui, lequel? | C14: =IF(ISBLANK('Autoévaluation client'!D14),0,1) -> 0 | D14: =IF(AND('Autoévaluation client'!D14="",'Autoévaluation client'!E14=""),"*","") -> * | E14: =IF(ISBLANK('Autoévaluation client'!F14),"",'Autoévaluation client'!F14) | M14: 0 | O14: =C14*M14 -> 0 | P14: =L14*M14 -> 0
A15: ='Autoévaluation client'!A15 -> 1.2. | B15: ='Autoévaluation client'!B15 -> Engagement de la direction | C15: =O15/N15 -> 0 | L15: =P15/N15 -> 0 | M15: 5 | N15: =SUM(M16:M28) -> 14 | O15: =SUM(O16:O28) -> 0 | P15: =SUM(P16:P28) -> 0 | Q15: =O15/$N15*$M15 -> 0 | R15: =P15/$N15*$M15 -> 0
A16: ='Autoévaluation client'!A16 -> 1.2.1. | B16: ='Autoévaluation client'!C16 -> La direction de l'entreprise montre-t-elle l'exemple à suivre en matière de sécurité et de santé à l'aide d'exigences, de décisions, de règles et d'instructions concrètes? | C16: =IF(ISBLANK('Autoévaluation client'!D16),0,1) -> 0 | D16: =IF(AND('Autoévaluation client'!D16="",'Autoévaluation client'!E16=""),"*","") -> * | E16: =IF(ISBLANK('Autoévaluation client'!F16),"",'Autoévaluation client'!F16) | M16: 5 | O16: =M16*C16 -> 0 | P16: =L16*M16 -> 0
A17: ='Autoévaluation client'!A17 -> 1.2.2. | B17: ='Autoévaluation client'!C17 -> Votre entreprise accorde-t-elle à la sécurité au travail la même valeur qu'à la qualité et à la productivité? | C17: =IF(ISBLANK('Autoévaluation client'!D17),0,1) -> 0 | D17: =IF(AND('Autoévaluation client'!D17="",'Autoévaluation client'!E17=""),"*","") -> * | E17: =IF(ISBLANK('Autoévaluation client'!F17),"",'Autoévaluation client'!F17) | M17: 5 | O17: =M17*C17 -> 0 | P17: =L17*M17 -> 0
A18: ='Autoévaluation client'!A18 -> 1.2.3. | B18: ='Autoévaluation client'!C18 -> La direction aborde-t-elle les situations et les comportements à risque lors de ses inspections dans les entreprises? | C18: =IF(ISBLANK('Autoévaluation client'!D18),0,1) -> 0 | D18: =IF(AND('Autoévaluation client'!D18="",'Autoévaluation client'!E18=""),"*","") -> * | E18: =IF(ISBLANK('Autoévaluation client'!F18),"",'Autoévaluation client'!F18) | M18: 3 | O18: =M18*C18 -> 0 | P18: =L18*M18 -> 0
A19: ='Autoévaluation client'!A19 -> 1.2.4. | B19: ='Autoévaluation client'!C19 -> Le budget prévoit-il des ressources pour la sécurité au travail et la protection de la santé? | C19: =IF(ISBLANK('Autoévaluation client'!D19),0,1) -> 0 | D19: =IF(AND('Autoévaluation client'!D19="",'Autoévaluation client'!E19=""),"*","") -> * | E19: =IF(ISBLANK('Autoévaluation client'!F19),"",'Autoévaluation client'!F19) | M19: 1 | O19: =M19*C19 -> 0 | P19: =L19*M19 -> 0
A20: ='Autoévaluation client'!A20 -> 1.2.5.a | B20: ='Autoévaluation client'!C20 -> La direction soutient-elle dans l'entreprise... les évaluations du risque? | C20: =IF(ISBLANK('Autoévaluation client'!D20),0,1) -> 0 | D20: =IF(AND('Autoévaluation client'!D20="",'Autoévaluation client'!E20=""),"*","") -> * | E20: =IF(ISBLANK('Autoévaluation client'!F20),"",'Autoévaluation client'!F20) | M20: 0 | O20: =M20*C20 -> 0 | P20: =L20*M20 -> 0
A21: ='Autoévaluation client'!A21 -> 1.2.5.b | B21: ='Autoévaluation client'!C21 -> les audits, les contrôles? | C21: =IF(ISBLANK('Autoévaluation client'!D21),0,1) -> 0 | D21: =IF(AND('Autoévaluation client'!D21="",'Autoévaluation client'!E21=""),"*","") -> * | E21: =IF(ISBLANK('Autoévaluation client'!F21),"",'Autoévaluation client'!F21) | M21: 0 | O21: =M21*C21 -> 0 | P21: =L21*M21 -> 0
A22: ='Autoévaluation client'!A22 -> 1.2.5.c | B22: ='Autoévaluation client'!C22 -> les analyses d'accidents? | C22: =IF(ISBLANK('Autoévaluation client'!D22),0,1) -> 0 | D22: =IF(AND('Autoévaluation client'!D22="",'Autoévaluation client'!E22=""),"*","") -> * | E22: =IF(ISBLANK('Autoévaluation client'!F22),"",'Autoévaluation client'!F22) | M22: 0 | O22: =M22*C22 -> 0 | P22: =L22*M22 -> 0
A23: ='Autoévaluation client'!A23 -> 1.2.5.d | B23: ='Autoévaluation client'!C23 -> la formation des collaborateurs sur le lieu de travail? | C23: =IF(ISBLANK('Autoévaluation client'!D23),0,1) -> 0 | D23: =IF(AND('Autoévaluation client'!D23="",'Autoévaluation client'!E23=""),"*","") -> * | E23: =IF(ISBLANK('Autoévaluation client'!F23),"",'Autoévaluation client'!F23) | M23: 0 | O23: =M23*C23 -> 0 | P23: =L23*M23 -> 0
A24: ='Autoévaluation client'!A24 -> 1.2.5.e | B24: ='Autoévaluation client'!C24 -> la mise en œuvre de mesures adéquates? | C24: =IF(ISBLANK('Autoévaluation client'!D24),0,1) -> 0 | D24: =IF(AND('Autoévaluation client'!D24="",'Autoévaluation client'!E24=""),"*","") -> * | E24: =IF(ISBLANK('Autoévaluation client'!F24),"",'Autoévaluation client'!F24) | M24: 0 | O24: =M24*C24 -> 0 | P24: =L24*M24 -> 0
A25: ='Autoévaluation client'!A25 -> 1.2.5.f | B25: ='Autoévaluation client'!C25 -> les campagnes en faveur de la sécurité au travail? | C25: =IF(ISBLANK('Autoévaluation client'!D25),0,1) -> 0 | D25: =IF(AND('Autoévaluation client'!D25="",'Autoévaluation client'!E25=""),"*","") -> * | E25: =IF(ISBLANK('Autoévaluation client'!F25),"",'Autoévaluation client'!F25) | M25: 0 | O25: =M25*C25 -> 0 | P25: =L25*M25 -> 0
A26: ='Autoévaluation client'!A26 -> 1.2.5.g | B26: ='Autoévaluation client'!C26 -> les campagnes en faveur de la sécurité durant les loisirs? | C26: =IF(ISBLANK('Autoévaluation client'!D26),0,1) -> 0 | D26: =IF(AND('Autoévaluation client'!D26="",'Autoévaluation client'!E26=""),"*","") -> * | E26: =IF(ISBLANK('Autoévaluation client'!F26),"",'Autoévaluation client'!F26) | M26: 0 | O26: =M26*C26 -> 0 | P26: =L26*M26 -> 0
A27: ='Autoévaluation client'!A27 -> 1.2.5.h | B27: ='Autoévaluation client'!C27 -> la gestion des absences? | C27: =IF(ISBLANK('Autoévaluation client'!D27),0,1) -> 0 | D27: =IF(AND('Autoévaluation client'!D27="",'Autoévaluation client'!E27=""),"*","") -> * | E27: =IF(ISBLANK('Autoévaluation client'!F27),"",'Autoévaluation client'!F27) | M27: 0 | O27: =M27*C27 -> 0 | P27: =L27*M27 -> 0
A28: ='Autoévaluation client'!A28 -> 1.2.5.i | B28: ='Autoévaluation client'!C28 -> autres? Si oui, lesquels? | C28: =IF(ISBLANK('Autoévaluation client'!D28),0,1) -> 0 | D28: =IF(AND('Autoévaluation client'!D28="",'Autoévaluation client'!E28=""),"*","") -> * | E28: =IF(ISBLANK('Autoévaluation client'!F28),"",'Autoévaluation client'!F28) | M28: 0 | O28: =M28*C28 -> 0 | P28: =L28*M28 -> 0
A29: ='Autoévaluation client'!A29 -> 1.3. | B29: ='Autoévaluation client'!B29 -> Engagement des supérieurs hiérarchiques | C29: =O29/N29 -> 0 | L29: =P29/N29 -> 0 | M29: 5 | N29: =SUM(M30:M41) -> 21 | O29: =SUM(O30:O41) -> 0 | P29: =SUM(P30:P41) -> 0 | Q29: =O29/$N29*$M29 -> 0 | R29: =P29/$N29*$M29 -> 0
A30: ='Autoévaluation client'!A30 -> 1.3.1.a | B30: ='Autoévaluation client'!C30 -> Les supérieurs hiérarchiques promeuvent-ils la sécurité et la santé : en se conformant aux prescriptions de sécurité (par ex. le port de l'équipement de protection individuelle (EPI))? | C30: =IF(ISBLANK('Autoévaluation client'!D30),0,1) -> 0 | D30: =IF(AND('Autoévaluation client'!D30="",'Autoévaluation client'!E30=""),"*","") -> * | E30: =IF(ISBLANK('Autoévaluation client'!F30),"",'Autoévaluation client'!F30) | M30: 5 | O30: =M30*C30 -> 0 | P30: =L30*M30 -> 0
A31: ='Autoévaluation client'!A31 -> 1.3.1.b | B31: ='Autoévaluation client'!C31 -> en faisant respecter l'observation des prescriptions de sécurité? | C31: =IF(ISBLANK('Autoévaluation client'!D31),0,1) -> 0 | D31: =IF(AND('Autoévaluation client'!D31="",'Autoévaluation client'!E31=""),"*","") -> * | E31: =IF(ISBLANK('Autoévaluation client'!F31),"",'Autoévaluation client'!F31) | M31: 5 | O31: =M31*C31 -> 0 | P31: =L31*M31 -> 0
A32: ='Autoévaluation client'!A32 -> 1.3.1.c | B32: ='Autoévaluation client'!C32 -> par d'autres formes d'incitations? Si oui, lesquelles? | C32: =IF(ISBLANK('Autoévaluation client'!D32),0,1) -> 0 | D32: =IF(AND('Autoévaluation client'!D32="",'Autoévaluation client'!E32=""),"*","") -> * | E32: =IF(ISBLANK('Autoévaluation client'!F32),"",'Autoévaluation client'!F32) | M32: 0 | O32: =M32*C32 -> 0 | P32: =L32*M32 -> 0
A33: ='Autoévaluation client'!A33 -> 1.3.2.a | B33: ='Autoévaluation client'!C33 -> Les supérieurs hiérarchiques de l'entreprise s'engagent-ils pour la sécurité et la santé des employés, en réalisant... des évaluations de risque? | C33: =IF(ISBLANK('Autoévaluation client'!D33),0,1) -> 0 | D33: =IF(AND('Autoévaluation client'!D33="",'Autoévaluation client'!E33=""),"*","") -> * | E33: =IF(ISBLANK('Autoévaluation client'!F33),"",'Autoévaluation client'!F33) | M33: 0 | O33: =M33*C33 -> 0 | P33: =L33*M33 -> 0
A34: ='Autoévaluation client'!A34 -> 1.3.2.b | B34: ='Autoévaluation client'!C34 -> des audits, des contrôles? | C34: =IF(ISBLANK('Autoévaluation client'!D34),0,1) -> 0 | D34: =IF(AND('Autoévaluation client'!D34="",'Autoévaluation client'!E34=""),"*","") -> * | E34: =IF(ISBLANK('Autoévaluation client'!F34),"",'Autoévaluation client'!F34) | M34: 2 | O34: =M34*C34 -> 0 | P34: =L34*M34 -> 0
A35: ='Autoévaluation client'!A35 -> 1.3.2.c | B35: ='Autoévaluation client'!C35 -> des analyses d'accidents? | C35: =IF(ISBLANK('Autoévaluation client'!D35),0,1) -> 0 | D35: =IF(AND('Autoévaluation client'!D35="",'Autoévaluation client'!E35=""),"*","") -> * | E35: =IF(ISBLANK('Autoévaluation client'!F35),"",'Autoévaluation client'!F35) | M35: 2 | O35: =M35*C35 -> 0 | P35: =L35*M35 -> 0
A36: ='Autoévaluation client'!A36 -> 1.3.2.d | B36: ='Autoévaluation client'!C36 -> de la formation des collaborateurs à la place de travail? | C36: =IF(ISBLANK('Autoévaluation client'!D36),0,1) -> 0 | D36: =IF(AND('Autoévaluation client'!D36="",'Autoévaluation client'!E36=""),"*","") -> * | E36: =IF(ISBLANK('Autoévaluation client'!F36),"",'Autoévaluation client'!F36) | M36: 2 | O36: =M36*C36 -> 0 | P36: =L36*M36 -> 0
A37: ='Autoévaluation client'!A37 -> 1.3.2.e | B37: ='Autoévaluation client'!C37 -> des campagnes en faveur de la sécurité au travail? | C37: =IF(ISBLANK('Autoévaluation client'!D37),0,1) -> 0 | D37: =IF(AND('Autoévaluation client'!D37="",'Autoévaluation client'!E37=""),"*","") -> * | E37: =IF(ISBLANK('Autoévaluation client'!F37),"",'Autoévaluation client'!F37) | M37: 0 | O37: =M37*C37 -> 0 | P37: =L37*M37 -> 0
A38: ='Autoévaluation client'!A38 -> 1.3.2.f | B38: ='Autoévaluation client'!C38 -> des campagnes en faveur de la sécurité durant les loisirs? | C38: =IF(ISBLANK('Autoévaluation client'!D38),0,1) -> 0 | D38: =IF(AND('Autoévaluation client'!D38="",'Autoévaluation client'!E38=""),"*","") -> * | E38: =IF(ISBLANK('Autoévaluation client'!F38),"",'Autoévaluation client'!F38) | M38: 0 | O38: =M38*C38 -> 0 | P38: =L38*M38 -> 0
A39: ='Autoévaluation client'!A39 -> 1.3.2.g | B39: ='Autoévaluation client'!C39 -> la gestion des absences? | C39: =IF(ISBLANK('Autoévaluation client'!D39),0,1) -> 0 | D39: =IF(AND('Autoévaluation client'!D39="",'Autoévaluation client'!E39=""),"*","") -> * | E39: =IF(ISBLANK('Autoévaluation client'!F39),"",'Autoévaluation client'!F39) | M39: 2 | O39: =M39*C39 -> 0 | P39: =L39*M39 -> 0
A40: ='Autoévaluation client'!A40 -> 1.3.2.h | B40: ='Autoévaluation client'!C40 -> d'autres actions? Si oui, lesquelles? | C40: =IF(ISBLANK('Autoévaluation client'!D40),0,1) -> 0 | D40: =IF(AND('Autoévaluation client'!D40="",'Autoévaluation client'!E40=""),"*","") -> * | E40: =IF(ISBLANK('Autoévaluation client'!F40),"",'Autoévaluation client'!F40) | M40: 0 | O40: =M40*C40 -> 0 | P40: =L40*M40 -> 0
...

Sheet Auswertungen
B2: Legende im Spinnendiagramm:
A3: Erfüllungsgrad | B3: ="Autoévaluation "&Analyse!B1 -> Autoévaluation Exemple SA | D3: Évaluation Suva | G3: Delta Suva - Kunde
B4: Berechnung automatisch | C4: Spinnendiagramm überschreibbar | D4: Berechnung automatisch | E4: Spinnendiagramm überschreibbar | G4: Zur Information
A5: =CONCATENATE(Analyse!A4," ",Analyse!B4) -> 1 Ligne de conduite, objectifs et stratégie | B5: =Analyse!C4 -> 0 | C5: =B5 -> 0 | D5: =Analyse!L4 -> 0 | E5: =D5 -> 0 | G5: =E5-C5 -> 0
A6: =CONCATENATE(Analyse!A64," ",Analyse!B64) -> 2. Organisation | B6: =Analyse!C64 -> 0 | C6: =B6 -> 0 | D6: =Analyse!L64 -> 0 | E6: =D6 -> 0 | G6: =E6-C6 -> 0
A7: =CONCATENATE(Analyse!A144," ",Analyse!B144) -> 3. Qualification, formation, communication | B7: =Analyse!C144 -> 0 | C7: =B7 -> 0 | D7: =Analyse!L144 -> 0 | E7: =D7 -> 0 | G7: =E7-C7 -> 0
A8: =CONCATENATE(Analyse!A240," ",Analyse!B240) -> 4. Règles de sécurité | B8: =Analyse!C240 -> 0.5 | C8: =B8 -> 0.5 | D8: =Analyse!L240 -> 0 | E8: =D8 -> 0 | G8: =E8-C8 -> -0.5
A9: =CONCATENATE(Analyse!A319," ",Analyse!B319) -> 5. Détermination des phénomènes dangereux et évaluation des risques | B9: =Analyse!C319 -> 0.034090909 | C9: =B9 -> 0.034090909 | D9: =Analyse!L319 -> 0.034090909 | E9: =D9 -> 0.034090909 | G9: =E9-C9 -> 0
A10: =CONCATENATE(Analyse!A368," ",Analyse!B368) -> 6. Mesures | B10: =Analyse!C368 -> 0 | C10: =B10 -> 0 | D10: =Analyse!L368 -> 0 | E10: =D10 -> 0 | G10: =E10-C10 -> 0
A11: =CONCATENATE(Analyse!A392," ",Analyse!B392) -> 7. Organisation en cas d’urgence | B11: =Analyse!C392 -> 0 | C11: =B11 -> 0 | D11: =Analyse!L392 -> 0 | E11: =D11 -> 0 | G11: =E11-C11 -> 0
A12: =CONCATENATE(Analyse!A429," ",Analyse!B429) -> 8. Participation | B12: =Analyse!C429 -> 0 | C12: =B12 -> 0 | D12: =Analyse!L429 -> 0 | E12: =D12 -> 0 | G12: =E12-C12 -> 0
A13: =CONCATENATE(Analyse!A445," ",Analyse!B445) -> 9. Protection de la santé | B13: =Analyse!C445 -> 0.15227273 | C13: =B13 -> 0.15227273 | D13: =Analyse!L445 -> 0.15227273 | E13: =D13 -> 0.15227273 | G13: =E13-C13 -> 0
A14: =CONCATENATE(Analyse!A556," ",Analyse!B556) -> 10. Contrôle, audit | B14: =Analyse!C556 -> 0 | C14: =B14 -> 0 | D14: =Analyse!L556 -> 0 | E14: =D14 -> 0 | G14: =E14-C14 -> 0
A15: =CONCATENATE(Analyse!A587," ",Analyse!B587) -> 11. Gestion des absences | B15: =Analyse!C587 -> 0 | C15: =B15 -> 0 | D15: =Analyse!L587 -> 0 | E15: =D15 -> 0 | G15: =E15-C15 -> 0
A16: =CONCATENATE(Analyse!A607," ",Analyse!B607) -> 12 Sécurité durant les loisirs (facultatif) | B16: =Analyse!C607 -> 0 | C16: =B16 -> 0 | D16: =Analyse!L607 -> 0 | E16: =D16 -> 0 | G16: =E16-C16 -> 0
A17: =CONCATENATE(Analyse!A629," ",Analyse!B629) -> 13 GSE: Gestion de la santé en entreprise (facultatif) | B17: =Analyse!C629 -> 0 | C17: =B17 -> 0 | D17: =Analyse!L629 -> 0 | E17: =D17 -> 0 | G17: =E17-C17 -> 0
A18: =CONCATENATE(Analyse!A657," ",Analyse!B657) -> 14 Extension pour ISO 45001 (facultatif) | B18: =Analyse!C657 -> 0 | C18: =B18 -> 0 | D18: =Analyse!L657 -> 0 | E18: =D18 -> 0 | G18: =E18-C18 -> 0

Sheet Versionenprotokoll
A1: Versionenprotokoll
A3: Version | B3: Sheet | C3: Änderungen
A4: Version 14 | B4: Selbstbeurteilung Kunde | C4: Französische Übersetzung der Frage 2.3.2.3. korrigiert
A5: Freigabe
A6: 45061
B7: Anleitung | C7: Versionnummer aktualisiert
B8: Selbstbeurteilung Kunde | C8: Versionnummer aktualisiert
A9: Version 13 | B9: verschiedene | C9: Formulierungen in der französischen Version kontrolliert und korrigiert durch Sandrine Casanova.
A10: Freigabe
A11: 45028
B12: Anleitung | C12: Versionnummer aktualisiert
B13: Selbstbeurteilung Kunde | C13: Versionnummer aktualisiert
A14: Version 12 | B14: Selbstbeurteilung Kunde | C14: In Fusszeile des Ausdrucks Versionnummer aktualisiert
A15: Freigabe | B15: Anleitung | C15: Versionnummer aktualisiert
A16: 44841 | B16: Analyse | C16: Spalte D "*" eingefügt zur Visualisierung nicht beantwortet.
B17: Analyse | C17: Spalte C formatiert für Visualisierung Ja / Nein
B18: Selbstbeurteilung Kunde | C18: In 9.9.8 und 9.9.9 Fragen 9.9 und 9.3 aus dem ASA-Systemkontrolle Kategorie 3.1 (EKAS 6074/3.1.d 02.2021) eingefügt.
A20: Version 11 | B20: Selbstbeurteilung Kunde | C20: In Fusszeile des Ausdrucks Versionnummer aktualisiert
A21: Freigabe | B21: Anleitung | C21: Versionnummer aktualisiert
A22: 43712 | B22: Selbstbeurteilung Kunde | C22: Anpassung von OHSAS 18001 auf ISO 45001
B23: Generell | C23: Suva Logo aktualisiert
B24: Analyse | C24: Anpassungen von OHSAS 18001 auf ISO 45001
A25: Version 10 | B25: Selbstbeurteilung Kunde | C25: In Fusszeile des Ausdrucks Versionnummer aktualisiert
A26: Freigabe | B26: Anleitung | C26: Versionnummer aktualisiert
A27: 42548 | B27: Analyse | C27: 2.1.3. Gewicht von 1 auf 2 erhöht
B28: Analyse | C28: 1.1.7. Gewicht von 5 auf 2 reduziert
B29: Analyse | C29: 4.1.3. Gewicht von 3 auf 1 reduziert
B30: Analyse | C30: 3.1. falscher Titel korrigiert (Zellenbezug 149 anstatt 148)
B31: Analyse | C31: 4.2. Gewicht von 1 auf 0 reduziert
B32: Analyse | C32: 4.3. Gewicht von 1 auf 2 erhöht
B33: Spinnendiagramme | C33: Legende "Beurteilung Suva" von D3 in Sheet Auswertungen
A35: Version 09 | B35: Selbstbeurteilung Kunde | C35: In Fusszeile des Ausdrucks Versionnummer aktualisiert
A36: Freigabe | B36: Anleitung | C36: Versionnummer aktualisiert
A37: 42555 | B37: Analyse | C37: Gewicht von Kapitel 9.3. physische Belastungen von 3 auf 0 geändert
B38: Analyse | C38: 9.10. Summierung der eigenen Punkte: Formel auf richtige Spalte korrigiert
B39: Analyse | C39: 4.8. Bewertung für Stichproben eingeführt
B40: Analyse | C40: 4.1.3 Gewicht für Booklet von 5 auf 3 reduziert
B41: Diagramme | C41: Rahmenlinie entfernt
A42: Version 08 | B42: Selbstbeurteilung Kunde | C42: In Fusszeile des Ausdrucks Versionnummer aktualisiert
A43: Freigabe | B43: Anleitung | C43: Versionnummer aktualisiert
...
