Workbook
Name Spinne1: Analyse!$C$4

Sheet Anleitung
A1: Anleitung zum Fragebogen "Selbstbeurteilung"
A2: Einleitung Sie haben beschlossen, Arbeitssicherheit und Gesundheitsschutz in Ihrem Unternehmen mit dem Projekt "Integrierten Sicherheit" systematisch zu verbessern. Dieser Fragebogen stellt hierbei ein zentrales Werkzeug dar. Er erlaubt es Ihnen, den Stand von Arbeitssicherheit und Gesundheitsschutz in Ihrem Unternehmen zu überprüfen und die für das Projekt notwendigen Informationen zu sammeln. Die folgenden Anmerkungen sollen beim Ausfüllen des Fragebogens behilflich sein.
A3: 1. Struktur des Fragebogens - Tabellenblätter: - Betriebsspiegel - Schlüsselpersonen der Arbeitssicherheit - Selbstbeurteilung Kunde - Übersicht Anhänge (Information)
A4: 2. Struktur der einzelnen Tabellenblätter - Nur Zellen die zum Ausfüllen vorgesehen sind, sind für die Bearbeitung freigeschaltet. - Zellbereiche die ausgefüllt werden müssen, sind zusätzlich grau schattiert. - Alle anderen freigeschalteten Bereiche können bei Bedarf ausgefüllt werden. - Schnelles Springen zwischen freigeschalteten Feldern ist mit der Tabulatorentaste möglich.
A5: 3. Tabellenblatt "Betriebsspiegel" - Ergänzen Sie die Spalte "Eintrag Kunde" mit den gefragten Informationen.
A6: 4. Tabellenblatt "Schlüsselpersonen Sicherheit" - Ergänzen Sie die Spalte "Funktion / Zuständigkeit" mit den im Unternehmen vorhandenen Funktionen. - Füllen Sie die Spalte "Name / Vorname" für sämtliche aufgeführten "Funktionen / Zuständigkeiten" aus, die im Unternehmen existieren.
A7: 5. Tabellenblatt "Selbstbeurteilung Kunde" - Beantworten Sie sämtliche Fragen mit "Ja" oder "Nein", indem Sie das entsprechende Feld mit einem "x" markieren. - Für Kommentare steht die Spalte "Bemerkung Kunde" zur Verfügung. - Bei einigen Fragen kann je nach Antwort auf die Ja/Nein-Frage ein Kommentar zwingend erforderlich sein (Spalte "Bemerkung Kunde" grau schattiert). - Manche Fragen bestehen aus mehreren Teilfragen. - In solchen Fällen ist die Fragestellung jeweils blau hinterlegt.
A8: 6. Anhänge - Bei manchen Fragen im Tabellenblatt "Selbstbeurteilung Kunde" ist ein Anhang als Dokumentation zwingend erforderlich (falls vorhanden). - Die Nummer des jeweiligen Anhangs ist in der Spalte "Anhang erforderlich" eingetragen. - Im Tabellenblatt "Übersicht Anhänge" werden sämtliche Anhangnummern erläutert. - Bei Bedarf können weitere Anhänge beigelegt werden. - Bitte senden Sie uns die Anhänge wenn möglich als PDF zu.
A9: FO.250.d.V14

Sheet Betriebsspiegel
A1: Betriebsspiegel
C2: Eintrag Kunde:
A3: 1. Firmenname | C3: Muster AG
A4: 2. Firmensitz
A5: 3.Gründung
A6: 4. Standorte
A7: 5. Rechtsform
A8: 6. Eigentümer
A9: 7. Organe
A10: 8. Produkte
A11: 9. Kunden
A12: 10. Umwelt- und Qualitätszertifikate
A13: 11. Firmendokumente
A14: 12. Organisationseinheiten des Unternehmens und Anzahl Mitarbeiter in jeder Organisationseinheit
A15: 13. Führungsspanne* in Ihrem Unternehmen *Führungsspanne: Anzahl der direkt untersellten Mitarbeiter eines Vorgesetzten | B15: auf der oberen Führungsebene
B16: auf der mittleren Führungsebene
B17: auf der unteren Führungsebene
A18: 14. Anzahl Mitarbeiter | B18: Geschäftsleitung
B19: Kader
B20: Mitarbeiter
B21: Lehrlinge
B22: Mitarbeiter Total
A23: 15. Tendenzielle Entwicklung Anzahl Mitarbeiter (Zunehmend / Konstant / Abnehmend) | B23: Kaderangehörige
B24: Mitarbeiter
B25: Lehrlinge
B26: Insgesamt
A27: 16. Ausbildungsstatus Mitarbeiter (Anteil in %) | B27: Hochschulabschluss
B28: Höhere Berufsausbildung (FH/TS)
B29: Berufsausbildung
B30: Anlehre
A31: 17. Nationalität der Mitarbeiter
A32: 18. Muttersprache der Mitarbeiter
A33: 19. Gefährdungsschwerpunkte

Sheet Schlüsselpersonen Sicherheit
A1: Schlüsselpersonen der Arbeitssicherheit
A2: Funktion / Zuständigkeit | B2: Name / Vorname
A3: Geschäftsleitung
A14: Abteilungsleiter ( sofern aus beigelegtem Organigramm nicht ersichtlich)
A26: Projektleitung / Projektteam IS
A37: Sicherheitsorganisation
A38: Sicherheitsbeauftragter
A39: Sicherheitsingenieur
A40: Sicherheitsfachmann
A41: Sicherheitsassistent
A42: Ergonomiebeauftragter
A43: Chemikalien-Ansprechperson
A44: Strahlenschutzverantwortlicher
A45: externe ASA-Spezialisten
... A121: Weitere Schlüsselpersonen (bei Bedarf ausfüllen)

Sheet Selbstbeurteilung Kunde
A1: Selbstbeurteilung Kunde
A2: Nr.SB | C2: Beschreibung Frage | D2: Ja | E2: Nein | F2: Bemerkung Kunde | G2: Anhang erforderlich
A3: 1. | B3: Leitbild, Sicherheitsziele und Strategien
B4: Visum Sachbearbeiter Kapitel 1.:
A5: 1.1. | B5: Unternehmensleitbild, Führungsgrundsätze
A6: 1.1.1. | C6: Verfügt das Unternehmen über ein Unternehmensleitbild? | D6: x | G6: 1.A
A7: 1.1.2. | C7: Sind Sicherheit und Gesundheit der Beschäftigten Bestandteil des Unternehmensleitbildes? | E7: x
A8: 1.1.3. | C8: Sind alle Mitarbeiter über den Sinn und die praktischen Konsequenzen des Unternehmensleitbildes informiert, resp. sind die Mitarbeiter „im Bild“? | D8: x | F8: Wir sprechen jedes Jahr darüber.
A9: 1.1.4. | C9: Stimmt das betriebliche Geschehen mit dem Unternehmensleitbild überein?
A10: 1.1.5. | C10: Richtet sich das Führungsverhalten der Vorgesetzten in Ihrem Unternehmen nach bestimmten Führungsgrundsätzen oder Führungsrichtlinien? Wenn ja, nach welchen?
A11: 1.1.6. | C11: Sind Sicherheit und Gesundheitsschutz ein ausdrücklicher Bestandteil der Führungsgrundsätze oder Führungsrichtlinien? | G11: 1.B
A12: 1.1.7. | C12: Hat das Unternehmen die Sicherheitscharta der Suva unterzeichnet?
A13: 1.1.8.a | C13: Ist eines der Folgenden Managementsysteme/Zertifizierungen im Betrieb eingefürt? ISO 9001, ISO 14001, ISO 45001, OHSAS18001 Falls ja, welches?
A14: 1.1.8.b | C14: Sind im Betrieb andere Managementsysteme/Zertifizierungen eingeführt? Falls ja, welche?
A15: 1.2. | B15: Engagement der Geschäftsleitung
A16: 1.2.1. | C16: Werden Sicherheit und Gesundheit von der obersten Geschäftsleitung vorgelebt und mit Forderungen, Entscheidungen, Regelungen und Anweisungen massgebend gefördert?
A17: 1.2.2. | C17: Hat in Ihrer Unternehmen Arbeitssicherheit den gleichen Stellenwert wie Qualität und Produktivität?
A18: 1.2.3. | C18: Spricht die Geschäftsleitung bei Betriebsrundgängen unsichere Zustände und Handlungen an?
A19: 1.2.4. | C19: Besteht für Arbeitssicherheit und Gesundheitsschutz eine Budgetposition?
A20: 1.2.5.a | C20: Unterstützt die Geschäftsleitung die folgenden Aktivitäten im Betrieb: Risikobeurteilungen?
A21: 1.2.5.b | C21: Audits und Kontrollen?
A22: 1.2.5.c | C22: Unfallabklärungen?
A23: 1.2.5.d | C23: Mitarbeiterschulungen am Arbeitsplatz?
A24: 1.2.5.e | C24: Umsetzung von Massnahmen?
A25: 1.2.5.f | C25: Kampagnen zur Arbeitssicherheit?
A26: 1.2.5.g | C26: Kampagnen zur Freizeitsicherheit?
A27: 1.2.5.h | C27: Absenzenmanagement?
A28: 1.2.5.i | C28: Weitere/andere? Falls ja, welche?
A29: 1.3. | B29: Engagement der Linienvorgesetzten
A30: 1.3.1.a | C30: Wird Sicherheit und Gesundheit von den Linienvorgesetzten gefördert durch: Vorleben der Sicherheitsvorschriften (z.B. Tragen von persönlicher Schutzausrüstung (PSA))?
A31: 1.3.1.b | C31: Durchsetzen von Sicherheitsvorschriften?
A32: 1.3.1.c | C32: Weitere/andere Verhaltensweisen und Anreize? Falls ja, welche?
A33: 1.3.2.a | C33: Engagieren sich die Linienvorgesetzten für Sicherheit und Gesundheit der Beschäftigten, indem sie die folgenden Aktivitäten durchführen: Risikobeurteilungen?
A34: 1.3.2.b | C34: Audits/Kontrollen?
A35: 1.3.2.c | C35: Unfallabklärungen?
A36: 1.3.2.d | C36: Mitarbeiterschulungen am Arbeitsplatz?
A37: 1.3.2.e | C37: Kampagnen für Arbeitssicherheit?
A38: 1.3.2.f | C38: Kampagnen für Freizeitsicherheit?
A39: 1.3.2.g | C39: Absenzenmanagement?
A40: 1.3.2.h | C40: Weitere/andere? Falls ja, welche?
...

Sheet Übersicht Anhänge
A1: Erforderliche Anhänge (falls vorhanden) Bitte senden Sie uns die Anhänge wenn möglich als PDF zu.
A2: Anhang Nr. | B2: Beschreibung
A3: 1.A | B3: Leitbild und Sicherheitsleitbild des Unternehmens
A4: 1.B | B4: Führungsgrundsätze des Unternehmens
A5: 1.C | B5: Schriftliche Definition der Sicherheitsziele des Unternehmens
A6: 2.A | B6: Organigramme des Unternehmens
A7: 2.B | B7: Stellenbeschreibung für Führungspositionen
A8: 2.C | B8: Stellenbeschreibung für Position ohne Führungsaufgaben
A9: 2.D | B9: Stellenbeschreibung für Sicherheitsbeauftragte
A10: 2.E | B10: Mitarbeitendenreglement des Unternehmens
A11: 2.F | B11: Weitere Organisationsdokumente die Aufgaben, Pflichten und Kompetenzen bezüglich Sicherheit und Gesundheit regeln
A12: 2.G | B12: Beispiel einer schriftlichen Arbeitsanweisung
A13: 2.H | B13: Betriebsordnung des Unternehmens
... A43: 11.B | B43: Ziele, Führungskennzahlen im Absenzenmanagement

Sheet Analyse
A1: Firma | B1: =Betriebsspiegel!C3 -> Muster AG | C1: Datum | E1: Nr.
A2: Analyse und Bewertung für Selbstbeuteilung und Ist-Aufnahme | C2: Antwort Kunde | F2: Interviewpartner | L2: Bewertung Suva | M2: Berechnung für Diagramm
C3: ja / nein | D3: * | E3: Bemerkungen des Kunden | F3: GL | G3: Führung | H3: HR | I3: Si Org | J3: VG | K3: MA | L3: Erfüllungsgrad in Prozent | M3: Gewicht | N3: max Punktzahl | O3: Punkte Selbst | P3: Punkte Suva | Q3: Level 1 Selbst | R3: Level 1 Suva
A4: 1 | B4: ='Selbstbeurteilung Kunde'!B3 -> Leitbild, Sicherheitsziele und Strategien | C4: =O4/N4 -> 0.035294118 | L4: =P4/N4 -> 0 | N4: =SUM(M5,M15,M29,M42,M56) -> 17 | O4: =SUM(Q5:Q63) -> 0.6 | P4: =SUM(R5:R63) -> 0
A5: ='Selbstbeurteilung Kunde'!A5 -> 1.1. | B5: ='Selbstbeurteilung Kunde'!B5 -> Unternehmensleitbild, Führungsgrundsätze | C5: =O5/N5 -> 0.2 | L5: =P5/N5 -> 0 | M5: 3 | N5: =SUM(M6:M14) -> 25 | O5: =SUM(O6:O14) -> 5 | P5: =SUM(P6:P14) -> 0 | Q5: =O5/$N5*$M5 -> 0.6 | R5: =P5/$N5*$M5 -> 0
A6: ='Selbstbeurteilung Kunde'!A6 -> 1.1.1. | B6: ='Selbstbeurteilung Kunde'!C6 -> Verfügt das Unternehmen über ein Unternehmensleitbild? | D6: =IF(AND('Selbstbeurteilung Kunde'!D6="",'Selbstbeurteilung Kunde'!E6=""),"*","") | E6: =IF(ISBLANK('Selbstbeurteilung Kunde'!F6),"",'Selbstbeurteilung Kunde'!F6) | M6: 3 | O6: =C6*M6 -> 0 | P6: =L6*M6 -> 0
A7: ='Selbstbeurteilung Kunde'!A7 -> 1.1.2. | B7: ='Selbstbeurteilung Kunde'!C7 -> Sind Sicherheit und Gesundheit der Beschäftigten Bestandteil des Unternehmensleitbildes? | C7: 0 | D7: =IF(AND('Selbstbeurteilung Kunde'!D7="",'Selbstbeurteilung Kunde'!E7=""),"*","") | E7: =IF(ISBLANK('Selbstbeurteilung Kunde'!F7),"",'Selbstbeurteilung Kunde'!F7) | M7: 4 | O7: =C7*M7 -> 0 | P7: =L7*M7 -> 0
A8: ='Selbstbeurteilung Kunde'!A8 -> 1.1.3. | B8: ='Selbstbeurteilung Kunde'!C8 -> Sind alle Mitarbeiter über den Sinn und die praktischen Konsequenzen des Unternehmensleitbildes informiert, resp. sind die Mitarbeiter „im Bild“? | C8: =IF(ISBLANK('Selbstbeurteilung Kunde'!D8),0,1) -> 1 | D8: =IF(AND('Selbstbeurteilung Kunde'!D8="",'Selbstbeurteilung Kunde'!E8=""),"*","") | E8: =IF(ISBLANK('Selbstbeurteilung Kunde'!F8),"",'Selbstbeurteilung Kunde'!F8) -> Wir sprechen jedes Jahr darüber. | M8: 5 | O8: =C8*M8 -> 5 | P8: =L8*M8 -> 0
A9: ='Selbstbeurteilung Kunde'!A9 -> 1.1.4. | B9: ='Selbstbeurteilung Kunde'!C9 -> Stimmt das betriebliche Geschehen mit dem Unternehmensleitbild überein? | C9: =IF(ISBLANK('Selbstbeurteilung Kunde'!D9),0,1) -> 0 | D9: =IF(AND('Selbstbeurteilung Kunde'!D9="",'Selbstbeurteilung Kunde'!E9=""),"*","") -> * | E9: =IF(ISBLANK('Selbstbeurteilung Kunde'!F9),"",'Selbstbeurteilung Kunde'!F9) | M9: 5 | O9: =C9*M9 -> 0 | P9: =L9*M9 -> 0
A10: ='Selbstbeurteilung Kunde'!A10 -> 1.1.5. | B10: ='Selbstbeurteilung Kunde'!C10 -> Richtet sich das Führungsverhalten der Vorgesetzten in Ihrem Unternehmen nach bestimmten Führungsgrundsätzen oder Führungsrichtlinien? Wenn ja, nach welchen? | C10: =IF(ISBLANK('Selbstbeurteilung Kunde'!D10),0,1) -> 0 | D10: =IF(AND('Selbstbeurteilung Kunde'!D10="",'Selbstbeurteilung Kunde'!E10=""),"*","") -> * | E10: =IF(ISBLANK('Selbstbeurteilung Kunde'!F10),"",'Selbstbeurteilung Kunde'!F10) | M10: 0 | O10: =C10*M10 -> 0 | P10: =L10*M10 -> 0
A11: ='Selbstbeurteilung Kunde'!A11 -> 1.1.6. | B11: ='Selbstbeurteilung Kunde'!C11 -> Sind Sicherheit und Gesundheitsschutz ein ausdrücklicher Bestandteil der Führungsgrundsätze oder Führungsrichtlinien? | C11: =IF(ISBLANK('Selbstbeurteilung Kunde'!D11),0,1) -> 0 | D11: =IF(AND('Selbstbeurteilung Kunde'!D11="",'Selbstbeurteilung Kunde'!E11=""),"*","") -> * | E11: =IF(ISBLANK('Selbstbeurteilung Kunde'!F11),"",'Selbstbeurteilung Kunde'!F11) | M11: 3 | O11: =C11*M11 -> 0 | P11: =L11*M11 -> 0
A12: ='Selbstbeurteilung Kunde'!A12 -> 1.1.7. | B12: ='Selbstbeurteilung Kunde'!C12 -> Hat das Unternehmen die Sicherheitscharta der Suva unterzeichnet? | C12: =IF(ISBLANK('Selbstbeurteilung Kunde'!D12),0,1) -> 0 | D12: =IF(AND('Selbstbeurteilung Kunde'!D12="",'Selbstbeurteilung Kunde'!E12=""),"*","") -> * | E12: =IF(ISBLANK('Selbstbeurteilung Kunde'!F12),"",'Selbstbeurteilung Kunde'!F12) | M12: 2 | O12: =C12*M12 -> 0 | P12: =L12*M12 -> 0
A13: ='Selbstbeurteilung Kunde'!A13 -> 1.1.8.a | B13: ='Selbstbeurteilung Kunde'!C13 -> Ist eines der Folgenden Managementsysteme/Zertifizierungen im Betrieb eingefürt? ISO 9001, ISO 14001, ISO 45001, OHSAS18001 Falls ja, welches? | C13: =IF(ISBLANK('Selbstbeurteilung Kunde'!D13),0,1) -> 0 | D13: =IF(AND('Selbstbeurteilung Kunde'!D13="",'Selbstbeurteilung Kunde'!E13=""),"*","") -> * | E13: =IF(ISBLANK('Selbstbeurteilung Kunde'!F13),"",'Selbstbeurteilung Kunde'!F13) | M13: 3 | O13: =C13*M13 -> 0 | P13: =L13*M13 -> 0
A14: ='Selbstbeurteilung Kunde'!A14 -> 1.1.8.b | B14: ='Selbstbeurteilung Kunde'!C14 -> Sind im Betrieb andere Managementsysteme/Zertifizierungen eingeführt? Falls ja, welche? | C14: =IF(ISBLANK('Selbstbeurteilung Kunde'!D14),0,1) -> 0 | D14: =IF(AND('Selbstbeurteilung Kunde'!D14="",'Selbstbeurteilung Kunde'!E14=""),"*","") -> * | E14: =IF(ISBLANK('Selbstbeurteilung Kunde'!F14),"",'Selbstbeurteilung Kunde'!F14) | M14: 0 | O14: =C14*M14 -> 0 | P14: =L14*M14 -> 0
A15: ='Selbstbeurteilung Kunde'!A15 -> 1.2. | B15: ='Selbstbeurteilung Kunde'!B15 -> Engagement der Geschäftsleitung | C15: =O15/N15 -> 0 | L15: =P15/N15 -> 0 | M15: 5 | N15: =SUM(M16:M28) -> 14 | O15: =SUM(O16:O28) -> 0 | P15: =SUM(P16:P28) -> 0 | Q15: =O15/$N15*$M15 -> 0 | R15: =P15/$N15*$M15 -> 0
A16: ='Selbstbeurteilung Kunde'!A16 -> 1.2.1. | B16: ='Selbstbeurteilung Kunde'!C16 -> Werden Sicherheit und Gesundheit von der obersten Geschäftsleitung vorgelebt und mit Forderungen, Entscheidungen, Regelungen und Anweisungen massgebend gefördert? | C16: =IF(ISBLANK('Selbstbeurteilung Kunde'!D16),0,1) -> 0 | D16: =IF(AND('Selbstbeurteilung Kunde'!D16="",'Selbstbeurteilung Kunde'!E16=""),"*","") -> * | E16: =IF(ISBLANK('Selbstbeurteilung Kunde'!F16),"",'Selbstbeurteilung Kunde'!F16) | M16: 5 | O16: =M16*C16 -> 0 | P16: =L16*M16 -> 0
A17: ='Selbstbeurteilung Kunde'!A17 -> 1.2.2. | B17: ='Selbstbeurteilung Kunde'!C17 -> Hat in Ihrer Unternehmen Arbeitssicherheit den gleichen Stellenwert wie Qualität und Produktivität? | C17: =IF(ISBLANK('Selbstbeurteilung Kunde'!D17),0,1) -> 0 | D17: =IF(AND('Selbstbeurteilung Kunde'!D17="",'Selbstbeurteilung Kunde'!E17=""),"*","") -> * | E17: =IF(ISBLANK('Selbstbeurteilung Kunde'!F17),"",'Selbstbeurteilung Kunde'!F17) | M17: 5 | O17: =M17*C17 -> 0 | P17: =L17*M17 -> 0
A18: ='Selbstbeurteilung Kunde'!A18 -> 1.2.3. | B18: ='Selbstbeurteilung Kunde'!C18 -> Spricht die Geschäftsleitung bei Betriebsrundgängen unsichere Zustände und Handlungen an? | C18: =IF(ISBLANK('Selbstbeurteilung Kunde'!D18),0,1) -> 0 | D18: =IF(AND('Selbstbeurteilung Kunde'!D18="",'Selbstbeurteilung Kunde'!E18=""),"*","") -> * | E18: =IF(ISBLANK('Selbstbeurteilung Kunde'!F18),"",'Selbstbeurteilung Kunde'!F18) | M18: 3 | O18: =M18*C18 -> 0 | P18: =L18*M18 -> 0
A19: ='Selbstbeurteilung Kunde'!A19 -> 1.2.4. | B19: ='Selbstbeurteilung Kunde'!C19 -> Besteht für Arbeitssicherheit und Gesundheitsschutz eine Budgetposition? | C19: =IF(ISBLANK('Selbstbeurteilung Kunde'!D19),0,1) -> 0 | D19: =IF(AND('Selbstbeurteilung Kunde'!D19="",'Selbstbeurteilung Kunde'!E19=""),"*","") -> * | E19: =IF(ISBLANK('Selbstbeurteilung Kunde'!F19),"",'Selbstbeurteilung Kunde'!F19) | M19: 1 | O19: =M19*C19 -> 0 | P19: =L19*M19 -> 0
A20: ='Selbstbeurteilung Kunde'!A20 -> 1.2.5.a | B20: ='Selbstbeurteilung Kunde'!C20 -> Unterstützt die Geschäftsleitung die folgenden Aktivitäten im Betrieb: Risikobeurteilungen? | C20: =IF(ISBLANK('Selbstbeurteilung Kunde'!D20),0,1) -> 0 | D20: =IF(AND('Selbstbeurteilung Kunde'!D20="",'Selbstbeurteilung Kunde'!E20=""),"*","") -> * | E20: =IF(ISBLANK('Selbstbeurteilung Kunde'!F20),"",'Selbstbeurteilung Kunde'!F20) | M20: 0 | O20: =M20*C20 -> 0 | P20: =L20*M20 -> 0
A21: ='Selbstbeurteilung Kunde'!A21 -> 1.2.5.b | B21: ='Selbstbeurteilung Kunde'!C21 -> Audits und Kontrollen? | C21: =IF(ISBLANK('Selbstbeurteilung Kunde'!D21),0,1) -> 0 | D21: =IF(AND('Selbstbeurteilung Kunde'!D21="",'Selbstbeurteilung Kunde'!E21=""),"*","") -> * | E21: =IF(ISBLANK('Selbstbeurteilung Kunde'!F21),"",'Selbstbeurteilung Kunde'!F21) | M21: 0 | O21: =M21*C21 -> 0 | P21: =L21*M21 -> 0
A22: ='Selbstbeurteilung Kunde'!A22 -> 1.2.5.c | B22: ='Selbstbeurteilung Kunde'!C22 -> Unfallabklärungen? | C22: =IF(ISBLANK('Selbstbeurteilung Kunde'!D22),0,1) -> 0 | D22: =IF(AND('Selbstbeurteilung Kunde'!D22="",'Selbstbeurteilung Kunde'!E22=""),"*","") -> * | E22: =IF(ISBLANK('Selbstbeurteilung Kunde'!F22),"",'Selbstbeurteilung Kunde'!F22) | M22: 0 | O22: =M22*C22 -> 0 | P22: =L22*M22 -> 0
A23: ='Selbstbeurteilung Kunde'!A23 -> 1.2.5.d | B23: ='Selbstbeurteilung Kunde'!C23 -> Mitarbeiterschulungen am Arbeitsplatz? | C23: =IF(ISBLANK('Selbstbeurteilung Kunde'!D23),0,1) -> 0 | D23: =IF(AND('Selbstbeurteilung Kunde'!D23="",'Selbstbeurteilung Kunde'!E23=""),"*","") -> * | E23: =IF(ISBLANK('Selbstbeurteilung Kunde'!F23),"",'Selbstbeurteilung Kunde'!F23) | M23: 0 | O23: =M23*C23 -> 0 | P23: =L23*M23 -> 0
A24: ='Selbstbeurteilung Kunde'!A24 -> 1.2.5.e | B24: ='Selbstbeurteilung Kunde'!C24 -> Umsetzung von Massnahmen? | C24: =IF(ISBLANK('Selbstbeurteilung Kunde'!D24),0,1) -> 0 | D24: =IF(AND('Selbstbeurteilung Kunde'!D24="",'Selbstbeurteilung Kunde'!E24=""),"*","") -> * | E24: =IF(ISBLANK('Selbstbeurteilung Kunde'!F24),"",'Selbstbeurteilung Kunde'!F24) | M24: 0 | O24: =M24*C24 -> 0 | P24: =L24*M24 -> 0
A25: ='Selbstbeurteilung Kunde'!A25 -> 1.2.5.f | B25: ='Selbstbeurteilung Kunde'!C25 -> Kampagnen zur Arbeitssicherheit? | C25: =IF(ISBLANK('Selbstbeurteilung Kunde'!D25),0,1) -> 0 | D25: =IF(AND('Selbstbeurteilung Kunde'!D25="",'Selbstbeurteilung Kunde'!E25=""),"*","") -> * | E25: =IF(ISBLANK('Selbstbeurteilung Kunde'!F25),"",'Selbstbeurteilung Kunde'!F25) | M25: 0 | O25: =M25*C25 -> 0 | P25: =L25*M25 -> 0
A26: ='Selbstbeurteilung Kunde'!A26 -> 1.2.5.g | B26: ='Selbstbeurteilung Kunde'!C26 -> Kampagnen zur Freizeitsicherheit? | C26: =IF(ISBLANK('Selbstbeurteilung Kunde'!D26),0,1) -> 0 | D26: =IF(AND('Selbstbeurteilung Kunde'!D26="",'Selbstbeurteilung Kunde'!E26=""),"*","") -> * | E26: =IF(ISBLANK('Selbstbeurteilung Kunde'!F26),"",'Selbstbeurteilung Kunde'!F26) | M26: 0 | O26: =M26*C26 -> 0 | P26: =L26*M26 -> 0
A27: ='Selbstbeurteilung Kunde'!A27 -> 1.2.5.h | B27: ='Selbstbeurteilung Kunde'!C27 -> Absenzenmanagement? | C27: =IF(ISBLANK('Selbstbeurteilung Kunde'!D27),0,1) -> 0 | D27: =IF(AND('Selbstbeurteilung Kunde'!D27="",'Selbstbeurteilung Kunde'!E27=""),"*","") -> * | E27: =IF(ISBLANK('Selbstbeurteilung Kunde'!F27),"",'Selbstbeurteilung Kunde'!F27) | M27: 0 | O27: =M27*C27 -> 0 | P27: =L27*M27 -> 0
A28: ='Selbstbeurteilung Kunde'!A28 -> 1.2.5.i | B28: ='Selbstbeurteilung Kunde'!C28 -> Weitere/andere? Falls ja, welche? | C28: =IF(ISBLANK('Selbstbeurteilung Kunde'!D28),0,1) -> 0 | D28: =IF(AND('Selbstbeurteilung Kunde'!D28="",'Selbstbeurteilung Kunde'!E28=""),"*","") -> * | E28: =IF(ISBLANK('Selbstbeurteilung Kunde'!F28),"",'Selbstbeurteilung Kunde'!F28) | M28: 0 | O28: =M28*C28 -> 0 | P28: =L28*M28 -> 0
A29: ='Selbstbeurteilung Kunde'!A29 -> 1.3. | B29: ='Selbstbeurteilung Kunde'!B29 -> Engagement der Linienvorgesetzten | C29: =O29/N29 -> 0 | L29: =P29/N29 -> 0 | M29: 5 | N29: =SUM(M30:M41) -> 21 | O29: =SUM(O30:O41) -> 0 | P29: =SUM(P30:P41) -> 0 | Q29: =O29/$N29*$M29 -> 0 | R29: =P29/$N29*$M29 -> 0
A30: ='Selbstbeurteilung Kunde'!A30 -> 1.3.1.a | B30: ='Selbstbeurteilung Kunde'!C30 -> Wird Sicherheit und Gesundheit von den Linienvorgesetzten gefördert durch: Vorleben der Sicherheitsvorschriften (z.B. Tragen von persönlicher Schutzausrüstung (PSA))? | C30: =IF(ISBLANK('Selbstbeurteilung Kunde'!D30),0,1) -> 0 | D30: =IF(AND('Selbstbeurteilung Kunde'!D30="",'Selbstbeurteilung Kunde'!E30=""),"*","") -> * | E30: =IF(ISBLANK('Selbstbeurteilung Kunde'!F30),"",'Selbstbeurteilung Kunde'!F30) | M30: 5 | O30: =M30*C30 -> 0 | P30: =L30*M30 -> 0
A31: ='Selbstbeurteilung Kunde'!A31 -> 1.3.1.b | B31: ='Selbstbeurteilung Kunde'!C31 -> Durchsetzen von Sicherheitsvorschriften? | C31: =IF(ISBLANK('Selbstbeurteilung Kunde'!D31),0,1) -> 0 | D31: =IF(AND('Selbstbeurteilung Kunde'!D31="",'Selbstbeurteilung Kunde'!E31=""),"*","") -> * | E31: =IF(ISBLANK('Selbstbeurteilung Kunde'!F31),"",'Selbstbeurteilung Kunde'!F31) | M31: 5 | O31: =M31*C31 -> 0 | P31: =L31*M31 -> 0
A32: ='Selbstbeurteilung Kunde'!A32 -> 1.3.1.c | B32: ='Selbstbeurteilung Kunde'!C32 -> Weitere/andere Verhaltensweisen und Anreize? Falls ja, welche? | C32: =IF(ISBLANK('Selbstbeurteilung Kunde'!D32),0,1) -> 0 | D32: =IF(AND('Selbstbeurteilung Kunde'!D32="",'Selbstbeurteilung Kunde'!E32=""),"*","") -> * | E32: =IF(ISBLANK('Selbstbeurteilung Kunde'!F32),"",'Selbstbeurteilung Kunde'!F32) | M32: 0 | O32: =M32*C32 -> 0 | P32: =L32*M32 -> 0
A33: ='Selbstbeurteilung Kunde'!A33 -> 1.3.2.a | B33: ='Selbstbeurteilung Kunde'!C33 -> Engagieren sich die Linienvorgesetzten für Sicherheit und Gesundheit der Beschäftigten, indem sie die folgenden Aktivitäten durchführen: Risikobeurteilungen? | C33: =IF(ISBLANK('Selbstbeurteilung Kunde'!D33),0,1) -> 0 | D33: =IF(AND('Selbstbeurteilung Kunde'!D33="",'Selbstbeurteilung Kunde'!E33=""),"*","") -> * | E33: =IF(ISBLANK('Selbstbeurteilung Kunde'!F33),"",'Selbstbeurteilung Kunde'!F33) | M33: 0 | O33: =M33*C33 -> 0 | P33: =L33*M33 -> 0
A34: ='Selbstbeurteilung Kunde'!A34 -> 1.3.2.b | B34: ='Selbstbeurteilung Kunde'!C34 -> Audits/Kontrollen? | C34: =IF(ISBLANK('Selbstbeurteilung Kunde'!D34),0,1) -> 0 | D34: =IF(AND('Selbstbeurteilung Kunde'!D34="",'Selbstbeurteilung Kunde'!E34=""),"*","") -> * | E34: =IF(ISBLANK('Selbstbeurteilung Kunde'!F34),"",'Selbstbeurteilung Kunde'!F34) | M34: 2 | O34: =M34*C34 -> 0 | P34: =L34*M34 -> 0
A35: ='Selbstbeurteilung Kunde'!A35 -> 1.3.2.c | B35: ='Selbstbeurteilung Kunde'!C35 -> Unfallabklärungen? | C35: =IF(ISBLANK('Selbstbeurteilung Kunde'!D35),0,1) -> 0 | D35: =IF(AND('Selbstbeurteilung Kunde'!D35="",'Selbstbeurteilung Kunde'!E35=""),"*","") -> * | E35: =IF(ISBLANK('Selbstbeurteilung Kunde'!F35),"",'Selbstbeurteilung Kunde'!F35) | M35: 2 | O35: =M35*C35 -> 0 | P35: =L35*M35 -> 0
A36: ='Selbstbeurteilung Kunde'!A36 -> 1.3.2.d | B36: ='Selbstbeurteilung Kunde'!C36 -> Mitarbeiterschulungen am Arbeitsplatz? | C36: =IF(ISBLANK('Selbstbeurteilung Kunde'!D36),0,1) -> 0 | D36: =IF(AND('Selbstbeurteilung Kunde'!D36="",'Selbstbeurteilung Kunde'!E36=""),"*","") -> * | E36: =IF(ISBLANK('Selbstbeurteilung Kunde'!F36),"",'Selbstbeurteilung Kunde'!F36) | M36: 2 | O36: =M36*C36 -> 0 | P36: =L36*M36 -> 0
A37: ='Selbstbeurteilung Kunde'!A37 -> 1.3.2.e | B37: ='Selbstbeurteilung Kunde'!C37 -> Kampagnen für Arbeitssicherheit? | C37: =IF(ISBLANK('Selbstbeurteilung Kunde'!D37),0,1) -> 0 | D37: =IF(AND('Selbstbeurteilung Kunde'!D37="",'Selbstbeurteilung Kunde'!E37=""),"*","") -> * | E37: =IF(ISBLANK('Selbstbeurteilung Kunde'!F37),"",'Selbstbeurteilung Kunde'!F37) | M37: 0 | O37: =M37*C37 -> 0 | P37: =L37*M37 -> 0
A38: ='Selbstbeurteilung Kunde'!A38 -> 1.3.2.f | B38: ='Selbstbeurteilung Kunde'!C38 -> Kampagnen für Freizeitsicherheit? | C38: =IF(ISBLANK('Selbstbeurteilung Kunde'!D38),0,1) -> 0 | D38: =IF(AND('Selbstbeurteilung Kunde'!D38="",'Selbstbeurteilung Kunde'!E38=""),"*","") -> * | E38: =IF(ISBLANK('Selbstbeurteilung Kunde'!F38),"",'Selbstbeurteilung Kunde'!F38) | M38: 0 | O38: =M38*C38 -> 0 | P38: =L38*M38 -> 0
A39: ='Selbstbeurteilung Kunde'!A39 -> 1.3.2.g | B39: ='Selbstbeurteilung Kunde'!C39 -> Absenzenmanagement? | C39: =IF(ISBLANK('Selbstbeurteilung Kunde'!D39),0,1) -> 0 | D39: =IF(AND('Selbstbeurteilung Kunde'!D39="",'Selbstbeurteilung Kunde'!E39=""),"*","") -> * | E39: =IF(ISBLANK('Selbstbeurteilung Kunde'!F39),"",'Selbstbeurteilung Kunde'!F39) | M39: 2 | O39: =M39*C39 -> 0 | P39: =L39*M39 -> 0
A40: ='Selbstbeurteilung Kunde'!A40 -> 1.3.2.h | B40: ='Selbstbeurteilung Kunde'!C40 -> Weitere/andere? Falls ja, welche? | C40: =IF(ISBLANK('Selbstbeurteilung Kunde'!D40),0,1) -> 0 | D40: =IF(AND('Selbstbeurteilung Kunde'!D40="",'Selbstbeurteilung Kunde'!E40=""),"*","") -> * | E40: =IF(ISBLANK('Selbstbeurteilung Kunde'!F40),"",'Selbstbeurteilung Kunde'!F40) | M40: 0 | O40: =M40*C40 -> 0 | P40: =L40*M40 -> 0
...

Sheet Auswertungen
B2: Legende im Spinnendiagramm:
A3: Erfüllungsgrad | B3: ="Selbstbeurteilung "&Analyse!B1 -> Selbstbeurteilung Muster AG | D3: Beurteilung Suva | G3: Delta Suva - Kunde
B4: Berechnung automatisch | C4: Spinnendiagramm überschreibbar | D4: Berechnung automatisch | E4: Spinnendiagramm überschreibbar | G4: Zur Information
A5: =CONCATENATE(Analyse!A4," ",Analyse!B4) -> 1 Leitbild, Sicherheitsziele und Strategien | B5: =Analyse!C4 -> 0.035294118 | C5: =B5 -> 0.035294118 | D5: =Analyse!L4 -> 0 | E5: =D5 -> 0 | G5: =E5-C5 -> -0.035294118
A6: =CONCATENATE(Analyse!A64," ",Analyse!B64) -> 2. Organisation | B6: =Analyse!C64 -> 0 | C6: =B6 -> 0 | D6: =Analyse!L64 -> 0 | E6: =D6 -> 0 | G6: =E6-C6 -> 0
A7: =CONCATENATE(Analyse!A144," ",Analyse!B144) -> 3. Befähigung, Schulung, Kommunikation | B7: =Analyse!C144 -> 0 | C7: =B7 -> 0 | D7: =Analyse!L144 -> 0 | E7: =D7 -> 0 | G7: =E7-C7 -> 0
A8: =CONCATENATE(Analyse!A240," ",Analyse!B240) -> 4. Sicherheitsstandards | B8: =Analyse!C240 -> 0 | C8: =B8 -> 0 | D8: =Analyse!L240 -> 0 | E8: =D8 -> 0 | G8: =E8-C8 -> 0
A9: =CONCATENATE(Analyse!A319," ",Analyse!B319) -> 5. Gefährdungsermittlung, Risikobeurteilung | B9: =Analyse!C319 -> 0.034090909 | C9: =B9 -> 0.034090909 | D9: =Analyse!L319 -> 0.034090909 | E9: =D9 -> 0.034090909 | G9: =E9-C9 -> 0
A10: =CONCATENATE(Analyse!A368," ",Analyse!B368) -> 6. Massnahmen | B10: =Analyse!C368 -> 0 | C10: =B10 -> 0 | D10: =Analyse!L368 -> 0 | E10: =D10 -> 0 | G10: =E10-C10 -> 0
A11: =CONCATENATE(Analyse!A392," ",Analyse!B392) -> 7. Notfallorganisation | B11: =Analyse!C392 -> 0 | C11: =B11 -> 0 | D11: =Analyse!L392 -> 0 | E11: =D11 -> 0 | G11: =E11-C11 -> 0
A12: =CONCATENATE(Analyse!A429," ",Analyse!B429) -> 8. Mitwirkung | B12: =Analyse!C429 -> 0 | C12: =B12 -> 0 | D12: =Analyse!L429 -> 0 | E12: =D12 -> 0 | G12: =E12-C12 -> 0
A13: =CONCATENATE(Analyse!A445," ",Analyse!B445) -> 9. Gesundheitsschutz | B13: =Analyse!C445 -> 0.15227273 | C13: =B13 -> 0.15227273 | D13: =Analyse!L445 -> 0.15227273 | E13: =D13 -> 0.15227273 | G13: =E13-C13 -> 0
A14: =CONCATENATE(Analyse!A556," ",Analyse!B556) -> 10. Kontrolle | B14: =Analyse!C556 -> 0 | C14: =B14 -> 0 | D14: =Analyse!L556 -> 0 | E14: =D14 -> 0 | G14: =E14-C14 -> 0
A15: =CONCATENATE(Analyse!A587," ",Analyse!B587) -> 11. Absenzenmanagement | B15: =Analyse!C587 -> 0 | C15: =B15 -> 0 | D15: =Analyse!L587 -> 0 | E15: =D15 -> 0 | G15: =E15-C15 -> 0
A16: =CONCATENATE(Analyse!A607," ",Analyse!B607) -> 12 Freizeitsicherheit (Fakultativ) | B16: =Analyse!C607 -> 0 | C16: =B16 -> 0 | D16: =Analyse!L607 -> 0 | E16: =D16 -> 0 | G16: =E16-C16 -> 0
A17: =CONCATENATE(Analyse!A629," ",Analyse!B629) -> 13 BGM: Betriebliches Gesundheitsmanagement (Fakultativ) | B17: =Analyse!C629 -> 0 | C17: =B17 -> 0 | D17: =Analyse!L629 -> 0 | E17: =D17 -> 0 | G17: =E17-C17 -> 0
A18: =CONCATENATE(Analyse!A657," ",Analyse!B657) -> 14 Erweiterung für ISO 45001 (Fakultativ) | B18: =Analyse!C657 -> 0 | C18: =B18 -> 0 | D18: =Analyse!L657 -> 0 | E18: =D18 -> 0 | G18: =E18-C18 -> 0

Sheet Versionenprotokoll
A2: Versionenprotokoll
A4: Version | B4: Sheet | C4: Änderungen
A5: Version 14 | B5: Selbstbeurteilung Kunde | C5: Französische Übersetzung der Frage 2.3.2.3. korrigiert
A6: Freigabe
A7: 45061
B8: Anleitung | C8: Versionnummer aktualisiert
B9: Selbstbeurteilung Kunde | C9: Versionnummer aktualisiert
A10: Version 13 | B10: verschiedene | C10: Formulierungen in der französischen Version kontrolliert und korrigiert durch Sandrine Casanova.
A11: Freigabe
A12: 45028
B13: Anleitung | C13: Versionnummer aktualisiert
B14: Selbstbeurteilung Kunde | C14: Versionnummer aktualisiert
A15: Version 12 | B15: Selbstbeurteilung Kunde | C15: In Fusszeile des Ausdrucks Versionnummer aktualisiert
A16: Freigabe | B16: Anleitung | C16: Versionnummer aktualisiert
A17: 44841 | B17: Analyse | C17: Spalte D "*" eingefügt zur Visualisierung nicht beantwortet.
B18: Analyse | C18: Spalte C formatiert für Visualisierung Ja / Nein
B19: Selbstbeurteilung Kunde | C19: In 9.9.8 und 9.9.9 Fragen 9.9 und 9.3 aus dem ASA-Systemkontrolle Kategorie 3.1 (EKAS 6074/3.1.d 02.2021) eingefügt.
A21: Version 11 | B21: Selbstbeurteilung Kunde | C21: In Fusszeile des Ausdrucks Versionnummer aktualisiert
A22: Freigabe | B22: Anleitung | C22: Versionnummer aktualisiert
A23: 43712 | B23: Selbstbeurteilung Kunde | C23: Anpassung von OHSAS 18001 auf ISO 45001
B24: Generell | C24: Suva Logo aktualisiert
B25: Analyse | C25: Anpassungen von OHSAS 18001 auf ISO 45001
A26: Version 10 | B26: Selbstbeurteilung Kunde | C26: In Fusszeile des Ausdrucks Versionnummer aktualisiert
A27: Freigabe | B27: Anleitung | C27: Versionnummer aktualisiert
A28: 42913 | B28: Analyse | C28: 2.1.3. Gewicht von 1 auf 2 erhöht
B29: Analyse | C29: 1.1.7. Gewicht von 5 auf 2 reduziert
B30: Analyse | C30: 4.1.3. Gewicht von 3 auf 1 reduziert
B31: Analyse | C31: 3.1. falscher Titel korrigiert (Zellenbezug 149 anstatt 148)
B32: Analyse | C32: 4.2. Gewicht von 1 auf 0 reduziert
B33: Analyse | C33: 4.3. Gewicht von 1 auf 2 erhöht
B34: Spinnendiagramme | C34: Legende "Beurteilung Suva" von D3 in Sheet Auswertungen
A36: Version 09 | B36: Selbstbeurteilung Kunde | C36: In Fusszeile des Ausdrucks Versionnummer aktualisiert
A37: Freigabe | B37: Anleitung | C37: Versionnummer aktualisiert
A38: 42555 | B38: Analyse | C38: Gewicht von Kapitel 9.3. physische Belastungen von 3 auf 0 geändert
B39: Analyse | C39: 9.10. Summierung der eigenen Punkte: Formel auf richtige Spalte korrigiert
B40: Analyse | C40: 4.8. Bewertung für Stichproben eingeführt
B41: Analyse | C41: 4.1.3 Gewicht für Booklet von 5 auf 3 reduziert
B42: Diagramme | C42: Rahmenlinie entfernt
A43: Version 08 | B43: Selbstbeurteilung Kunde | C43: In Fusszeile des Ausdrucks Versionnummer aktualisiert
A44: Freigabe | B44: Anleitung | C44: Versionnummer aktualisiert
...
